Workbook

Sheet PV
A1: Database | B1: PV
A3: Activity | B3: 1,1-difluoroethane production, HFC-152a
A4: comment | B4: Basic inventory based on cumulative data. Pre-products, energy use, infrastructure, some air emissions and transports. No full information on all air and water emissions available. Location: Production plant of DuPont in the United States. Technology: Fluoropolymer chemistry. Time period: Time of publications. Production volume: Not known Sampling: Publication of cumulative data. Extrapolations: Desaggregation of published cumulative results for global warming potential and cumulative energy demand. Uncertainty: None
A5: location | B5: US
A6: production amount | B6: 1
A7: reference product | B7: 1,1-difluoroethane, HFC-152a
A8: source | B8: Fthenakis, V., Leccisi, E., & Frischknecht, Rolf; Stolz, Philippe; Krebs, Luana; de Wild-Scholten, Mariska; Sinha, P. (2021). Life Cycle Inventories and Life Cycle Assessments of Photovoltaic Systems 2020 Task 12 PV Sustainability. Progress in Photovoltaics: Research and Applications, 29(10), 1068–1077. www.iea-pvps.org
A9: type | B9: process
A10: unit | B10: kilogram
A11: Exchanges
A12: name | B12: amount | C12: location | D12: unit | E12: categories | F12: type | G12: uncertainty type | H12: loc | I12: scale | J12: comment | K12: negative | L12: reference product
A13: Ethane, 1,1-difluoro-, HFC-152a | B13: 0.013583 | D13: kilogram | E13: air::urban air close to ground | F13: biosphere | G13: 2 | H13: -4.2989363 | I13: 0.30183001 | J13: (5,3,1,1,1,5); Rough estimation based on cumulative data, Krieger et al. 2006
A14: Heat, waste | B14: 3.92 | D14: megajoule | E14: air | F14: biosphere | G14: 2 | H14: 1.3660917 | I14: 0.22493235 | J14: (5,3,1,1,1,5); Rough estimation based on cumulative data, Krieger et al. 2006
A15: 1,1-difluoroethane production, HFC-152a | B15: 1 | C15: US | D15: kilogram | E15: chemicals::organics | F15: production | G15: 0 | H15: 1 | L15: 1,1-difluoroethane, HFC-152a
A16: acetylene production | B16: 0.42733 | C16: RER | D16: kilogram | F16: technosphere | G16: 2 | H16: -0.85019873 | I16: 0.22493235 | J16: (5,3,1,1,1,5); Acetylen yield is 92.4% | L16: acetylene
A17: chemical factory construction, organics | B17: 4e-10 | C17: RER | D17: unit | F17: technosphere | G17: 2 | H17: -21.639557 | I17: 0.59308259 | J17: (5,3,1,1,1,5); Rough estimation based on cumulative data, Krieger et al. 2006 | L17: chemical factory, organics
A18: heat production, natural gas, at industrial furnace >100kW | B18: 0.98 | C18: Europe without Switzerland | D18: megajoule | F18: technosphere | G18: 2 | H18: -0.020202707 | I18: 0.22493235 | J18: (5,3,1,1,1,5); Rough estimation based on cumulative data, Krieger et al. 2006 | L18: heat, district or industrial, natural gas
A19: hydrogen fluoride production | B19: 0.63699 | C19: GLO | D19: kilogram | F19: technosphere | G19: 2 | H19: -0.45100132 | I19: 0.22493235 | J19: (5,3,1,1,1,5); Rough estimation based on cumulative data, Krieger et al. 2006 | L19: hydrogen fluoride
A20: lime production, hydrated, packed | B20: 0.021387 | C20: CH | D20: kilogram | F20: technosphere | G20: 2 | H20: -3.844972 | I20: 0.22493235 | J20: (5,3,1,1,1,5); Rough estimation based on cumulative data, Krieger et al. 2006 | L20: lime, hydrated, packed
A21: market for electricity, medium voltage | B21: 1.0889 | C21: RS | D21: kilowatt hour | F21: technosphere | G21: 2 | H21: 0.085168012 | I21: 0.22493235 | J21: (5,3,1,1,1,5); Rough estimation based on cumulative data, Krieger et al. 2006 | L21: electricity, medium voltage
A22: market for transport, freight, sea, container ship | B22: 6.3699 | C22: GLO | D22: ton kilometer | F22: technosphere | G22: 2 | H22: 1.8515838 | I22: 0.41246039 | J22: (5,3,1,1,1,5); Rough estimation based on cumulative data, Krieger et al. 2006 | L22: transport, freight, sea, container ship
A23: market for zinc | B23: 0.0019676 | C23: GLO | D23: kilogram | F23: technosphere | G23: 2 | H23: -6.2309408 | I23: 0.22493235 | J23: (5,3,1,1,1,5); Rough estimation based on cumulative data, Krieger et al. 2006 | L23: zinc
A24: transport, freight train, diesel | B24: 0.27041 | C24: Europe without Switzerland | D24: ton kilometer | F24: technosphere | G24: 2 | H24: -1.307816 | I24: 0.41246039 | J24: (5,3,1,1,1,5); Rough estimation based on cumulative data, Krieger et al. 2006 | L24: transport, freight train
A25: transport, freight, lorry 7.5-16 metric ton, EURO4 | B25: 0.10877 | C25: RER | D25: ton kilometer | F25: technosphere | G25: 2 | H25: -2.2185197 | I25: 0.41246039 | J25: (5,3,1,1,1,5); Rough estimation based on cumulative data, Krieger et al. 2006 | L25: transport, freight, lorry 7.5-16 metric ton, EURO4
A27: Activity | B27: photovoltaic slanted-roof installation, 1.3 MWp, multi-Si, panel, mounted, on roof
A28: comment | B28: Photovoltaic installation with a capacity of 1300kWp and a life time of 30 years installed in Switzerland. The efficiency of multi-Si PV modules is 16.8% (Fraunhofer ISE Photovoltaics Report 2019). The share of rejected or replaced PV modules is estimated at 3%. The inverter is assumed to be replaced once during the service life of the PV system. All components (modules, mounting system, electric installation, inverter) for the installation of a 1300 kWp photovoltaic plant, energy use for the mounting, transport of materials to the place of installation. Disposal of components after end of life. Location: Installation in CH Technology: Current technology for mounting of panels or laminates, electric installations and other components. Sampling: Questionnaire filled in by the engineer of the plant (Hostettler). Extrapolations: none Uncertainty: none
A29: location | B29: CH
A30: production amount | B30: 1
A31: reference product | B31: photovoltaic slanted-roof installation, 1.3 MWp, multi-Si, panel, mounted, on roof
A32: source | B32: Fthenakis, V., Leccisi, E., & Frischknecht, Rolf; Stolz, Philippe; Krebs, Luana; de Wild-Scholten, Mariska; Sinha, P. (2021). Life Cycle Inventories and Life Cycle Assessments of Photovoltaic Systems 2020 Task 12 PV Sustainability. Progress in Photovoltaics: Research and Applications, 29(10), 1068–1077. www.iea-pvps.org
A33: type | B33: process
A34: unit | B34: unit
A35: Exchanges
A36: name | B36: amount | C36: location | D36: unit | E36: categories | F36: type | G36: uncertainty type | H36: loc | I36: scale | J36: comment | K36: negative | L36: reference product
A37: Heat, waste | B37: 371.5 | D37: megajoule | E37: air::urban air close to ground | F37: biosphere | G37: 2 | H37: 5.9175489 | I37: 0.36098878 | J37: (1,na,na,na,na,na); calculated with electricity use
A38: photovoltaic slanted-roof installation, 1.3 MWp, multi-Si, panel, mounted, on roof | B38: 1 | C38: CH | D38: unit | E38: Electricity by fuel::Photovoltaic\Infrastructure | F38: production | G38: 0 | H38: 1 | L38: photovoltaic slanted-roof installation, 1.3 MWp, multi-Si, panel, mounted, on roof
A39: electric installation, 1.3 MWp photovoltaic plant, at plant | B39: 1 | C39: CH | D39: unit | F39: technosphere | G39: 2 | H39: 0 | I39: 0.74824658 | J39: (3,4,1,1,1,5);
A40: inverter production, 500kW | B40: 4.4132 | C40: RER | D40: unit | F40: technosphere | G40: 2 | H40: 1.4846 | I40: 0.74824658 | J40: (2,4,1,1,1,5); 1 replacement in the life time | L40: inverter, 500kW
A41: market for electricity, low voltage | B41: 103.19 | C41: CH | D41: kilowatt hour | F41: technosphere | G41: 2 | H41: 4.6365719 | I41: 0.5093334 | J41: (3,4,3,1,1,5); scaled from a 3kWp plant over capacity | L41: electricity, low voltage
A42: photovoltaic panel, multi-Si, at regional storage | B42: 7438.9 | C42: RER | D42: square meter | F42: technosphere | G42: 2 | H42: 8.9144783 | I42: 0.74824658 | J42: (3,4,1,1,1,5); calculation with maximum power output and module efficiency; 2% of modules replaced in the life time, 1% rejects
...

Sheet PV (extension)
A1: Activity | B1: electricity production, photovoltaic, residential
A2: comment | B2: =_xlfn._LONGTEXT("Dataset created adapted from the methodology followed by: Life Cycle Inventories and Life Cycle Assessments of Photovoltaic Systems 2020 Task 12 PV Sustainability, December 2020, DOI: 10.13140/RG.2.2.17977.19041 However, the technology split is not countr","y-specific but based based on weighted average of OECD countries. Production volume provided by IRENA 2025: https://www.irena.org/Publications/2025/Jul/Renewable-energy-statistics-2025 Open-ground PV panel productivity in the country based on area-weighte","d estimate from the Global Solar Atlas: https://globalsolaratlas.info/download/world The lifetime of PV systems is estimated at 30 years based on the PEFCR PV electricity. Production mix of photovoltaic electricity in the country. Annual output, Roof-Top",": ")&HLOOKUP(B3,parameters!$C$195:$EJ$198,2,0)&" kWh/kWp. Annual output, Facade: "&HLOOKUP(B3,parameters!$C$195:$EJ$198,3,0)&" kWh/kWp. Annual output, Open-ground: "&HLOOKUP(B3,parameters!$C$195:$EJ$198,4,0)&_xlfn._LONGTEXT(" kWh/kWp. Amount of solar energy transformed to electricity. Waste heat emission due to losses of electricity in the system. Technology: Electricity production with grid-connected photovoltaic power plants. Time period: Time of publications Production v","olume: ")&VLOOKUP(B3,'extension - production vol'!$B$6:$D$235,3,0)&_xlfn._LONGTEXT(" GWh in 2025. Sampling: Statistical data and model calculations Extrapolations: Use of PV technology data investigated for other countries (Switzerland). Correction of average yield with Swiss data. Uncertainty: None Author: Romain Sacchi, PSI, romain.","sacchi@psi.ch") -> Dataset created adapted from the methodology followed by: Life Cycle Inventories and Life Cycle Assessments of Photovoltaic Systems 2020 Task 12 PV Sustainability, December 2020, DOI: 10.13140/RG.2.2.17977.19041 However, the technology split is not country-specific but based based on weighted average of OECD countries. Production volume provided by IRENA 2025: https://www.irena.org/Publications/2025/Jul/Renewable-energy-statistics-2025 Open-ground PV panel productivity in the country based on area-weighted estimate from the Global Solar Atlas: https://globalsolaratlas.info/download/world The lifetime of PV systems is estimated at 30 years based on the PEFCR PV electricity. Production mix of photovoltaic electricity in the country. Annual output, Roof-Top: 1860.26870229946 kWh/kWp. Annual output, Facade: 1306.14611012515 kWh/kWp. Annual output, Open-ground: 1979.00925776538 kWh/kWp. Amount of solar energy transformed to electricity. Waste heat emission due to losses of electricity in the system. Technology: Electricity production with grid-connected photovoltaic power plants. Time period: Time of publications Production volume: 13.901 GWh in 2025. Sampling: Statistical data and model calculations Extrapolations: Use of PV technology data investigated for other countries (Switzerland). Correction of average yield with Swiss data. Uncertainty: None Author: Romain Sacchi, PSI, romain.sacchi@psi.ch
A3: location | B3: NA
A4: production amount | B4: 1
A5: reference product | B5: electricity, low voltage
A6: source | B6: Fthenakis, V., Leccisi, E., & Frischknecht, Rolf; Stolz, Philippe; Krebs, Luana; de Wild-Scholten, Mariska; Sinha, P. (2021). Life Cycle Inventories and Life Cycle Assessments of Photovoltaic Systems 2020 Task 12 PV Sustainability. Progress in Photovoltaics: Research and Applications, 29(10), 1068–1077. www.iea-pvps.org
A7: type | B7: process
A8: unit | B8: kilowatt hour
A9: Exchanges
A10: name | B10: amount | C10: location | D10: unit | E10: categories | F10: type | G10: uncertainty type | H10: reference product | I10: comment | J10: production volume | K10: scope | L10: scope share | M10: tech share | N10: installation | O10: productivity | P10: kWp | Q10: lifetime | R10: lifetime production | S10: inverted lifetime production
A11: Energy, solar, converted | B11: 3.8503 | D11: megajoule | E11: natural resource::in air | F11: biosphere | G11: 0 | I11: (2,2,1,1,1,3); Energy loss in the system
A12: Heat, waste | B12: 0.25027 | D12: megajoule | E12: air | F12: biosphere | G12: 0 | I12: (1,na,na,na,na,na); Calculation with average annual output and share of technologies; Average degradation of 10.5% included
A13: electricity production, photovoltaic, residential | B13: 1 | C13: NA | D13: kilowatt hour | E13: photovoltaic::power plants | F13: production | G13: 0 | H13: electricity, low voltage | J13: =VLOOKUP(C13,'extension - production vol'!$B$6:$D$235,3,0) -> 13.901
A14: photovoltaic slanted-roof installation, 3 kWp, CIS, laminated, integrated, on roof | B14: =M14*S14 -> 3.057995e-08 | C14: CH | D14: unit | F14: technosphere | G14: 0 | H14: photovoltaic slanted-roof installation, 3 kWp, CIS, laminated, integrated, on roof | I14: (2,2,1,1,1,3); Calculation with average annual yield and share of technologies. Lifetime: 30a. | K14: residential | L14: =IF(K14="residential",VLOOKUP(B3,parameters!$C$41:$AG$178,18,0),IF(K14="commercial",1-VLOOKUP(B3,parameters!$C$41:$AG$178,18,0),1)) -> 0.17766752 | M14: =INDEX(parameters!$D$41:$AG$178,MATCH('PV (extension)'!B3,parameters!$C$41:$C$178,0),MATCH('PV (extension)'!A14,parameters!$D$5:$AG$5,0))/L14 -> 0.0051198231 | N14: roof-top | O14: =INDEX(parameters!$C$196:$EJ$198,MATCH('PV (extension)'!N14,parameters!$B$196:$B$198,0),MATCH('PV (extension)'!B3,parameters!$C$195:$EJ$195,0)) -> 1860.2687 | P14: 3 | Q14: 30 | R14: =Q14*P14*O14 -> 167424.18 | S14: =1/R14 -> 5.9728528e-06
A15: photovoltaic slanted-roof installation, 3 kWp, CdTe, panel, mounted, on roof | B15: =M15*S15 -> 1.9945179e-07 | C15: CH | D15: unit | F15: technosphere | G15: 0 | H15: photovoltaic slanted-roof installation, 3 kWp, CdTe, panel, mounted, on roof | I15: (2,2,1,1,1,3); Calculation with average annual yield and share of technologies. Lifetime: 30a. | K15: residential | L15: =L14 -> 0.17766752 | M15: =INDEX(parameters!$D$41:$AG$178,MATCH('PV (extension)'!B3,parameters!$C$41:$C$178,0),MATCH('PV (extension)'!A15,parameters!$D$5:$AG$5,0))/L15 -> 0.033393054 | N15: roof-top | O15: =INDEX(parameters!$C$196:$EJ$198,MATCH('PV (extension)'!N15,parameters!$B$196:$B$198,0),MATCH('PV (extension)'!B3,parameters!$C$195:$EJ$195,0)) -> 1860.2687 | P15: 3 | Q15: 30 | R15: =Q15*P15*O15 -> 167424.18 | S15: =1/R15 -> 5.9728528e-06
A16: photovoltaic slanted-roof installation, 3 kWp, micro-Si, laminated, integrated, on roof | B16: =M16*S16 -> 3.0905029e-09 | C16: RER | D16: unit | F16: technosphere | G16: 0 | H16: photovoltaic slanted-roof installation, 3 kWp, micro-Si, laminated, integrated, on roof | I16: (2,2,1,1,1,3); Calculation with average annual yield and share of technologies. Lifetime: 30a. | K16: residential | L16: =L15 -> 0.17766752 | M16: =INDEX(parameters!$D$41:$AG$178,MATCH('PV (extension)'!B3,parameters!$C$41:$C$178,0),MATCH('PV (extension)'!A16,parameters!$D$5:$AG$5,0))/L16 -> 0.00051742493 | N16: roof-top | O16: =INDEX(parameters!$C$196:$EJ$198,MATCH('PV (extension)'!N16,parameters!$B$196:$B$198,0),MATCH('PV (extension)'!B3,parameters!$C$195:$EJ$195,0)) -> 1860.2687 | P16: 3 | Q16: 30 | R16: =Q16*P16*O16 -> 167424.18 | S16: =1/R16 -> 5.9728528e-06
A17: photovoltaic slanted-roof installation, 3 kWp, micro-Si, panel, mounted, on roof | B17: =M17*S17 -> 5.3727857e-08 | C17: RER | D17: unit | F17: technosphere | G17: 0 | H17: photovoltaic slanted-roof installation, 3 kWp, micro-Si, panel, mounted, on roof | I17: (2,2,1,1,1,3); Calculation with average annual yield and share of technologies. Lifetime: 30a. | K17: residential | L17: =L16 -> 0.17766752 | M17: =INDEX(parameters!$D$41:$AG$178,MATCH('PV (extension)'!B3,parameters!$C$41:$C$178,0),MATCH('PV (extension)'!A17,parameters!$D$5:$AG$5,0))/L17 -> 0.0089953426 | N17: roof-top | O17: =INDEX(parameters!$C$196:$EJ$198,MATCH('PV (extension)'!N17,parameters!$B$196:$B$198,0),MATCH('PV (extension)'!B3,parameters!$C$195:$EJ$195,0)) -> 1860.2687 | P17: 3 | Q17: 30 | R17: =Q17*P17*O17 -> 167424.18 | S17: =1/R17 -> 5.9728528e-06
A18: photovoltaic facade installation, 3kWp, multi-Si, laminated, integrated, at building | B18: =M18*S18 -> 1.5735721e-07 | C18: RER | D18: unit | F18: technosphere | G18: 0 | H18: photovoltaic facade installation, 3kWp, multi-Si, laminated, integrated, at building | I18: (2,2,1,1,1,3); Calculation with average annual yield and share of technologies. Lifetime: 30a. | K18: residential | L18: =L17 -> 0.17766752 | M18: =INDEX(parameters!$D$41:$AG$178,MATCH('PV (extension)'!B3,parameters!$C$41:$C$178,0),MATCH('PV (extension)'!A18,parameters!$D$5:$AG$5,0))/L18 -> 0.018497835 | N18: façade | O18: =INDEX(parameters!$C$196:$EJ$198,MATCH('PV (extension)'!N18,parameters!$B$196:$B$198,0),MATCH('PV (extension)'!B3,parameters!$C$195:$EJ$195,0)) -> 1306.1461 | P18: 3 | Q18: 30 | R18: =Q18*P18*O18 -> 117553.15 | S18: =1/R18 -> 8.5067903e-06
A19: photovoltaic facade installation, 3kWp, multi-Si, panel, mounted, at building | B19: =M19*S19 -> 1.5432577e-07 | C19: RER | D19: unit | F19: technosphere | G19: 0 | H19: photovoltaic facade installation, 3kWp, multi-Si, panel, mounted, at building | I19: (2,2,1,1,1,3); Calculation with average annual yield and share of technologies. Lifetime: 30a. | K19: residential | L19: =L18 -> 0.17766752 | M19: =INDEX(parameters!$D$41:$AG$178,MATCH('PV (extension)'!B3,parameters!$C$41:$C$178,0),MATCH('PV (extension)'!A19,parameters!$D$5:$AG$5,0))/L19 -> 0.018141481 | N19: façade | O19: =INDEX(parameters!$C$196:$EJ$198,MATCH('PV (extension)'!N19,parameters!$B$196:$B$198,0),MATCH('PV (extension)'!B3,parameters!$C$195:$EJ$195,0)) -> 1306.1461 | P19: 3 | Q19: 30 | R19: =Q19*P19*O19 -> 117553.15 | S19: =1/R19 -> 8.5067903e-06
A20: photovoltaic facade installation, 3kWp, single-Si, laminated, integrated, at building | B20: =M20*S20 -> 8.2956962e-08 | C20: RER | D20: unit | F20: technosphere | G20: 0 | H20: photovoltaic facade installation, 3kWp, single-Si, laminated, integrated, at building | I20: (2,2,1,1,1,3); Calculation with average annual yield and share of technologies. Lifetime: 30a. | K20: residential | L20: =L19 -> 0.17766752 | M20: =INDEX(parameters!$D$41:$AG$178,MATCH('PV (extension)'!B3,parameters!$C$41:$C$178,0),MATCH('PV (extension)'!A20,parameters!$D$5:$AG$5,0))/L20 -> 0.0097518522 | N20: façade | O20: =INDEX(parameters!$C$196:$EJ$198,MATCH('PV (extension)'!N20,parameters!$B$196:$B$198,0),MATCH('PV (extension)'!B3,parameters!$C$195:$EJ$195,0)) -> 1306.1461 | P20: 3 | Q20: 30 | R20: =Q20*P20*O20 -> 117553.15 | S20: =1/R20 -> 8.5067903e-06
A21: photovoltaic facade installation, 3kWp, single-Si, panel, mounted, at building | B21: =M21*S21 -> 8.2885184e-08 | C21: RER | D21: unit | F21: technosphere | G21: 0 | H21: photovoltaic facade installation, 3kWp, single-Si, panel, mounted, at building | I21: (2,2,1,1,1,3); Calculation with average annual yield and share of technologies. Lifetime: 30a. | K21: residential | L21: =L20 -> 0.17766752 | M21: =INDEX(parameters!$D$41:$AG$178,MATCH('PV (extension)'!B3,parameters!$C$41:$C$178,0),MATCH('PV (extension)'!A21,parameters!$D$5:$AG$5,0))/L21 -> 0.0097434145 | N21: façade | O21: =INDEX(parameters!$C$196:$EJ$198,MATCH('PV (extension)'!N21,parameters!$B$196:$B$198,0),MATCH('PV (extension)'!B3,parameters!$C$195:$EJ$195,0)) -> 1306.1461 | P21: 3 | Q21: 30 | R21: =Q21*P21*O21 -> 117553.15 | S21: =1/R21 -> 8.5067903e-06
A22: photovoltaic flat-roof installation, 3kWp, multi-Si, on roof | B22: =M22*S22 -> 1.7019211e-06 | C22: RER | D22: unit | F22: technosphere | G22: 0 | H22: photovoltaic flat-roof installation, 3kWp, multi-Si, on roof | I22: (2,2,1,1,1,3); Calculation with average annual yield and share of technologies. Lifetime: 30a. | K22: residential | L22: =L21 -> 0.17766752 | M22: =INDEX(parameters!$D$41:$AG$178,MATCH('PV (extension)'!B3,parameters!$C$41:$C$178,0),MATCH('PV (extension)'!A22,parameters!$D$5:$AG$5,0))/L22 -> 0.28494275 | N22: roof-top | O22: =INDEX(parameters!$C$196:$EJ$198,MATCH('PV (extension)'!N22,parameters!$B$196:$B$198,0),MATCH('PV (extension)'!B3,parameters!$C$195:$EJ$195,0)) -> 1860.2687 | P22: 3 | Q22: 30 | R22: =Q22*P22*O22 -> 167424.18 | S22: =1/R22 -> 5.9728528e-06
A23: photovoltaic flat-roof installation, 3kWp, single-Si, on roof | B23: =M23*S23 -> 8.8837815e-07 | C23: RER | D23: unit | F23: technosphere | G23: 0 | H23: photovoltaic flat-roof installation, 3kWp, single-Si, on roof | I23: (2,2,1,1,1,3); Calculation with average annual yield and share of technologies. Lifetime: 30a. | K23: residential | L23: =L22 -> 0.17766752 | M23: =INDEX(parameters!$D$41:$AG$178,MATCH('PV (extension)'!B3,parameters!$C$41:$C$178,0),MATCH('PV (extension)'!A23,parameters!$D$5:$AG$5,0))/L23 -> 0.14873599 | N23: roof-top | O23: =INDEX(parameters!$C$196:$EJ$198,MATCH('PV (extension)'!N23,parameters!$B$196:$B$198,0),MATCH('PV (extension)'!B3,parameters!$C$195:$EJ$195,0)) -> 1860.2687 | P23: 3 | Q23: 30 | R23: =Q23*P23*O23 -> 167424.18 | S23: =1/R23 -> 5.9728528e-06
A24: photovoltaic slanted-roof installation, 3kWp, CIS, panel, mounted, on roof | B24: =M24*S24 -> 4.9137815e-07 | C24: CH | D24: unit | F24: technosphere | G24: 0 | H24: photovoltaic slanted-roof installation, 3kWp, CIS, panel, mounted, on roof | I24: (2,2,1,1,1,3); Calculation with average annual yield and share of technologies. Lifetime: 30a. | K24: residential | L24: =L23 -> 0.17766752 | M24: =INDEX(parameters!$D$41:$AG$178,MATCH('PV (extension)'!B3,parameters!$C$41:$C$178,0),MATCH('PV (extension)'!A24,parameters!$D$5:$AG$5,0))/L24 -> 0.082268586 | N24: roof-top | O24: =INDEX(parameters!$C$196:$EJ$198,MATCH('PV (extension)'!N24,parameters!$B$196:$B$198,0),MATCH('PV (extension)'!B3,parameters!$C$195:$EJ$195,0)) -> 1860.2687 | P24: 3 | Q24: 30 | R24: =Q24*P24*O24 -> 167424.18 | S24: =1/R24 -> 5.9728528e-06
A25: photovoltaic slanted-roof installation, 3kWp, CdTe, laminated, integrated, on roof | B25: =M25*S25 -> 1.3758896e-08 | C25: CH | D25: unit | F25: technosphere | G25: 0 | H25: photovoltaic slanted-roof installation, 3kWp, CdTe, laminated, integrated, on roof | I25: (2,2,1,1,1,3); Calculation with average annual yield and share of technologies. Lifetime: 30a. | K25: residential | L25: =L24 -> 0.17766752 | M25: =INDEX(parameters!$D$41:$AG$178,MATCH('PV (extension)'!B3,parameters!$C$41:$C$178,0),MATCH('PV (extension)'!A25,parameters!$D$5:$AG$5,0))/L25 -> 0.002303572 | N25: roof-top | O25: =INDEX(parameters!$C$196:$EJ$198,MATCH('PV (extension)'!N25,parameters!$B$196:$B$198,0),MATCH('PV (extension)'!B3,parameters!$C$195:$EJ$195,0)) -> 1860.2687 | P25: 3 | Q25: 30 | R25: =Q25*P25*O25 -> 167424.18 | S25: =1/R25 -> 5.9728528e-06
A26: photovoltaic slanted-roof installation, 3kWp, multi-Si, laminated, integrated, on roof | B26: =M26*S26 -> 8.1742412e-08 | C26: RER | D26: unit | F26: technosphere | G26: 0 | H26: photovoltaic slanted-roof installation, 3kWp, multi-Si, laminated, integrated, on roof | I26: (2,2,1,1,1,3); Calculation with average annual yield and share of technologies. Lifetime: 30a. | K26: residential | L26: =L25 -> 0.17766752 | M26: =INDEX(parameters!$D$41:$AG$178,MATCH('PV (extension)'!B3,parameters!$C$41:$C$178,0),MATCH('PV (extension)'!A26,parameters!$D$5:$AG$5,0))/L26 -> 0.013685656 | N26: roof-top | O26: =INDEX(parameters!$C$196:$EJ$198,MATCH('PV (extension)'!N26,parameters!$B$196:$B$198,0),MATCH('PV (extension)'!B3,parameters!$C$195:$EJ$195,0)) -> 1860.2687 | P26: 3 | Q26: 30 | R26: =Q26*P26*O26 -> 167424.18 | S26: =1/R26 -> 5.9728528e-06
A27: photovoltaic slanted-roof installation, 3kWp, multi-Si, panel, mounted, on roof | B27: =M27*S27 -> 1.3991397e-06 | C27: RER | D27: unit | F27: technosphere | G27: 0 | H27: photovoltaic slanted-roof installation, 3kWp, multi-Si, panel, mounted, on roof | I27: (2,2,1,1,1,3); Calculation with average annual yield and share of technologies. Lifetime: 30a. | K27: residential | L27: =L26 -> 0.17766752 | M27: =INDEX(parameters!$D$41:$AG$178,MATCH('PV (extension)'!B3,parameters!$C$41:$C$178,0),MATCH('PV (extension)'!A27,parameters!$D$5:$AG$5,0))/L27 -> 0.23424983 | N27: roof-top | O27: =INDEX(parameters!$C$196:$EJ$198,MATCH('PV (extension)'!N27,parameters!$B$196:$B$198,0),MATCH('PV (extension)'!B3,parameters!$C$195:$EJ$195,0)) -> 1860.2687 | P27: 3 | Q27: 30 | R27: =Q27*P27*O27 -> 167424.18 | S27: =1/R27 -> 5.9728528e-06
A28: photovoltaic slanted-roof installation, 3kWp, single-Si, laminated, integrated, on roof | B28: =M28*S28 -> 4.3200561e-08 | C28: RER | D28: unit | F28: technosphere | G28: 0 | H28: photovoltaic slanted-roof installation, 3kWp, single-Si, laminated, integrated, on roof | I28: (2,2,1,1,1,3); Calculation with average annual yield and share of technologies. Lifetime: 30a. | K28: residential | L28: =L27 -> 0.17766752 | M28: =INDEX(parameters!$D$41:$AG$178,MATCH('PV (extension)'!B3,parameters!$C$41:$C$178,0),MATCH('PV (extension)'!A28,parameters!$D$5:$AG$5,0))/L28 -> 0.0072328187 | N28: roof-top | O28: =INDEX(parameters!$C$196:$EJ$198,MATCH('PV (extension)'!N28,parameters!$B$196:$B$198,0),MATCH('PV (extension)'!B3,parameters!$C$195:$EJ$195,0)) -> 1860.2687 | P28: 3 | Q28: 30 | R28: =Q28*P28*O28 -> 167424.18 | S28: =1/R28 -> 5.9728528e-06
A29: photovoltaic slanted-roof installation, 3kWp, single-Si, panel, mounted, on roof | B29: =M29*S29 -> 7.312001e-07 | C29: RER | D29: unit | F29: technosphere | G29: 0 | H29: photovoltaic slanted-roof installation, 3kWp, single-Si, panel, mounted, on roof | I29: (2,2,1,1,1,3); Calculation with average annual yield and share of technologies. Lifetime: 30a. | K29: residential | L29: =L28 -> 0.17766752 | M29: =INDEX(parameters!$D$41:$AG$178,MATCH('PV (extension)'!B3,parameters!$C$41:$C$178,0),MATCH('PV (extension)'!A29,parameters!$D$5:$AG$5,0))/L29 -> 0.12242058 | N29: roof-top | O29: =INDEX(parameters!$C$196:$EJ$198,MATCH('PV (extension)'!N29,parameters!$B$196:$B$198,0),MATCH('PV (extension)'!B3,parameters!$C$195:$EJ$195,0)) -> 1860.2687 | P29: 3 | Q29: 30 | R29: =Q29*P29*O29 -> 167424.18 | S29: =1/R29 -> 5.9728528e-06
A30: market for tap water | B30: 0.0037026 | C30: Europe without Switzerland | D30: kilogram | F30: technosphere | G30: 0 | H30: tap water | I30: (2,2,1,1,1,3); Estimation 20l/m2 panel
A31: treatment of wastewater, from residence, capacity 1.1E10l/year | B31: -3.3323e-06 | C31: CH | D31: cubic meter | F31: technosphere | G31: 0 | H31: wastewater, from residence | I31: (2,2,1,1,1,3); Estimation 20l/m2 panel
A33: Activity | B33: electricity production, photovoltaic, commercial
A34: comment | B34: =_xlfn._LONGTEXT("Dataset created adapted from the methodology followed by: Life Cycle Inventories and Life Cycle Assessments of Photovoltaic Systems 2020 Task 12 PV Sustainability, December 2020, DOI: 10.13140/RG.2.2.17977.19041 However, the technology split is not countr","y-specific but based based on weighted average of OECD countries. Production volume provided by IRENA 2025: https://www.irena.org/Publications/2025/Jul/Renewable-energy-statistics-2025 Open-ground PV panel productivity in the country based on area-weighte","d estimate from the Global Solar Atlas: https://globalsolaratlas.info/download/world The lifetime of PV systems is estimated at 30 years based on the PEFCR PV electricity. Production mix of photovoltaic electricity in the country. Annual output, Roof-Top",": ")&HLOOKUP(B35,parameters!$C$195:$EJ$198,2,0)&" kWh/kWp. Annual output, Facade: "&HLOOKUP(B35,parameters!$C$195:$EJ$198,3,0)&" kWh/kWp. Annual output, Open-ground: "&HLOOKUP(B35,parameters!$C$195:$EJ$198,4,0)&_xlfn._LONGTEXT(" kWh/kWp. Amount of solar energy transformed to electricity. Waste heat emission due to losses of electricity in the system. Technology: Electricity production with grid-connected photovoltaic power plants. Time period: Time of publications Production v","olume: ")&VLOOKUP(B35,'extension - production vol'!$B$6:$D$235,3,0)&_xlfn._LONGTEXT(" GWh in 2025. Sampling: Statistical data and model calculations Extrapolations: Use of PV technology data investigated for other countries (Switzerland). Correction of average yield with Swiss data. Uncertainty: None Author: Romain Sacchi, PSI, romain.","sacchi@psi.ch") -> Dataset created adapted from the methodology followed by: Life Cycle Inventories and Life Cycle Assessments of Photovoltaic Systems 2020 Task 12 PV Sustainability, December 2020, DOI: 10.13140/RG.2.2.17977.19041 However, the technology split is not country-specific but based based on weighted average of OECD countries. Production volume provided by IRENA 2025: https://www.irena.org/Publications/2025/Jul/Renewable-energy-statistics-2025 Open-ground PV panel productivity in the country based on area-weighted estimate from the Global Solar Atlas: https://globalsolaratlas.info/download/world The lifetime of PV systems is estimated at 30 years based on the PEFCR PV electricity. Production mix of photovoltaic electricity in the country. Annual output, Roof-Top: 1860.26870229946 kWh/kWp. Annual output, Facade: 1306.14611012515 kWh/kWp. Annual output, Open-ground: 1979.00925776538 kWh/kWp. Amount of solar energy transformed to electricity. Waste heat emission due to losses of electricity in the system. Technology: Electricity production with grid-connected photovoltaic power plants. Time period: Time of publications Production volume: 13.901 GWh in 2025. Sampling: Statistical data and model calculations Extrapolations: Use of PV technology data investigated for other countries (Switzerland). Correction of average yield with Swiss data. Uncertainty: None Author: Romain Sacchi, PSI, romain.sacchi@psi.ch
A35: location | B35: NA
A36: production amount | B36: 1
A37: reference product | B37: electricity, low voltage
A38: source | B38: Fthenakis, V., Leccisi, E., & Frischknecht, Rolf; Stolz, Philippe; Krebs, Luana; de Wild-Scholten, Mariska; Sinha, P. (2021). Life Cycle Inventories and Life Cycle Assessments of Photovoltaic Systems 2020 Task 12 PV Sustainability. Progress in Photovoltaics: Research and Applications, 29(10), 1068–1077. www.iea-pvps.org
A39: type | B39: process
A40: unit | B40: kilowatt hour
A41: Exchanges
...

Sheet parameters
A1: skip
B2: source | C2: https://www.researchgate.net/publication/347999880_Life_Cycle_Inventories_and_Life_Cycle_Assessments_of_Photovoltaic_Systems_2020_Task_12_PV_Sustainability?channel=doi&linkId=5fec5fa4a6fdccdcb81714bd&showFulltext=true
B4: shares | D4: Residential | V4: Commercial | AH4: Sum | AJ4: Production volumes (GWh, IRENA 2025)
D5: photovoltaic facade installation, 3kWp, single-Si, laminated, integrated, at building | E5: photovoltaic facade installation, 3kWp, single-Si, panel, mounted, at building | F5: photovoltaic facade installation, 3kWp, multi-Si, laminated, integrated, at building | G5: photovoltaic facade installation, 3kWp, multi-Si, panel, mounted, at building | H5: photovoltaic flat-roof installation, 3kWp, single-Si, on roof | I5: photovoltaic flat-roof installation, 3kWp, multi-Si, on roof | J5: photovoltaic slanted-roof installation, 3kWp, CdTe, laminated, integrated, on roof | K5: photovoltaic slanted-roof installation, 3 kWp, CdTe, panel, mounted, on roof | L5: photovoltaic slanted-roof installation, 3 kWp, CIS, laminated, integrated, on roof | M5: photovoltaic slanted-roof installation, 3kWp, CIS, panel, mounted, on roof | N5: photovoltaic slanted-roof installation, 3 kWp, micro-Si, laminated, integrated, on roof | O5: photovoltaic slanted-roof installation, 3 kWp, micro-Si, panel, mounted, on roof | P5: photovoltaic slanted-roof installation, 3kWp, single-Si, laminated, integrated, on roof | Q5: photovoltaic slanted-roof installation, 3kWp, single-Si, panel, mounted, on roof | R5: photovoltaic slanted-roof installation, 3kWp, multi-Si, laminated, integrated, on roof | S5: photovoltaic slanted-roof installation, 3kWp, multi-Si, panel, mounted, on roof | T5: sum | V5: photovoltaic flat-roof installation, 156 kWp, single-Si, on roof | W5: photovoltaic flat-roof installation, 156 kWp, multi-Si, on roof | X5: photovoltaic slanted-roof installation, 93 kWp, single-Si, laminated, integrated, on roof | Y5: photovoltaic slanted-roof installation, 93 kWp, single-Si, panel, mounted, on roof | Z5: photovoltaic slanted-roof installation, 93 kWp, multi-Si, laminated, integrated, on roof | AA5: photovoltaic slanted-roof installation, 93 kWp, multi-Si, panel, mounted, on roof | AB5: photovoltaic open ground installation, 570 kWp, single-Si, on open ground | AC5: photovoltaic open ground installation, 570 kWp, multi-Si, on open ground | AD5: photovoltaic open ground installation, 570 kWp, CdTe, on open ground | AE5: photovoltaic open ground installation, 570 kWp, CIS, on open ground | AF5: photovoltaic open ground installation, 570 kWp, micro-Si, on open ground | AG5: sum
B6: Australia | C6: AU | D6: 0.00255 | E6: 0.00255 | F6: 0.00482 | G6: 0.00482 | H6: 0.0383 | I6: 0.0723 | J6: 0.000984 | K6: 0.0164 | L6: 0.000813 | M6: 0.0136 | N6: 0.000128 | O6: 0.00214 | P6: 0.00189 | Q6: 0.0314 | R6: 0.00356 | S6: 0.0593 | T6: =SUM(D6:S6) -> 0.255555 | V6: 0.0766 | W6: 0.145 | X6: 0.00511 | Y6: 0.0851 | Z6: 0.00964 | AA6: 0.161 | AB6: 0.0868 | AC6: 0.164 | AD6: 0.0062 | AE6: 0.00512 | AF6: 0.000808 | AG6: =SUM(V6:AF6) -> 0.745378 | AH6: =SUM(V6:AF6,D6:S6) -> 1.000933 | AJ6: =VLOOKUP(C6,'extension - production vol'!$B$6:$D$235,3,0) -> 41964.6
B7: Austria | C7: AT | D7: 0.000419 | E7: 0 | F7: 0.00643 | G7: 0 | H7: 0.00998 | I7: 0.153 | J7: 0.000301 | K7: 0.00992 | L7: 0.000249 | M7: 0.0082 | N7: 3.93e-05 | O7: 0.00129 | P7: 0.000267 | Q7: 0.00879 | R7: 0.00409 | S7: 0.135 | T7: =SUM(D7:S7) -> 0.3379753 | V7: 0.02 | W7: 0.306 | X7: 0.000606 | Y7: 0.02 | Z7: 0.00929 | AA7: 0.306 | AB7: 0 | AC7: 0 | AD7: 0 | AE7: 0 | AF7: 0 | AG7: =SUM(V7:AF7) -> 0.661896 | AH7: =SUM(V7:AF7,D7:S7) -> 0.9998713 | AJ7: =VLOOKUP(C7,'extension - production vol'!$B$6:$D$235,3,0) -> 6394.811
B8: Belgium | C8: BE | D8: 0.00285 | E8: 0.00285 | F8: 0.00537 | G8: 0.00537 | H8: 0.0427 | I8: 0.0806 | J8: 0.0011 | K8: 0.0183 | L8: 0.000906 | M8: 0.0151 | N8: 0.000143 | O8: 0.00239 | P8: 0.0021 | Q8: 0.035 | R8: 0.00397 | S8: 0.0662 | T8: =SUM(D8:S8) -> 0.284949 | V8: 0.0854 | W8: 0.161 | X8: 0.00569 | Y8: 0.0948 | Z8: 0.0107 | AA8: 0.179 | AB8: 0.0588 | AC8: 0.111 | AD8: 0.0042 | AE8: 0.00347 | AF8: 0.000548 | AG8: =SUM(V8:AF8) -> 0.714608 | AH8: =SUM(V8:AF8,D8:S8) -> 0.999557 | AJ8: =VLOOKUP(C8,'extension - production vol'!$B$6:$D$235,3,0) -> 7820
B9: Canada | C9: CA | D9: 0.00121 | E9: 0.00121 | F9: 0.00229 | G9: 0.00229 | H9: 0.0182 | I9: 0.0344 | J9: 0.000468 | K9: 0.0078 | L9: 0.000387 | M9: 0.00645 | N9: 6.11e-05 | O9: 0.00102 | P9: 0.000897 | Q9: 0.0149 | R9: 0.00169 | S9: 0.0282 | T9: =SUM(D9:S9) -> 0.1214731 | V9: 0.0364 | W9: 0.0688 | X9: 0.00243 | Y9: 0.0405 | Z9: 0.00459 | AA9: 0.0764 | AB9: 0.214 | AC9: 0.405 | AD9: 0.0153 | AE9: 0.0127 | AF9: 0.002 | AG9: =SUM(V9:AF9) -> 0.87812 | AH9: =SUM(V9:AF9,D9:S9) -> 0.9995931 | AJ9: =VLOOKUP(C9,'extension - production vol'!$B$6:$D$235,3,0) -> 7071
B10: Chile | C10: CL | D10: 3.21e-05 | E10: 3.21e-05 | F10: 6.07e-05 | G10: 6.07e-05 | H10: 0.000482 | I10: 0.00091 | J10: 1.24e-05 | K10: 0.000206 | L10: 1.02e-05 | M10: 0.000171 | N10: 1.62e-06 | O10: 2.69e-05 | P10: 2.37e-05 | Q10: 0.000396 | R10: 4.48e-05 | S10: 0.000747 | T10: =SUM(D10:S10) -> 0.00321722 | V10: 0.000964 | W10: 0.00182 | X10: 6.43e-05 | Y10: 0.00107 | Z10: 0.000121 | AA10: 0.00202 | AB10: 0.327 | AC10: 0.618 | AD10: 0.0234 | AE10: 0.0193 | AF10: 0.00305 | AG10: =SUM(V10:AF10) -> 0.9968093 | AH10: =SUM(V10:AF10,D10:S10) -> 1.0000265 | AJ10: =VLOOKUP(C10,'extension - production vol'!$B$6:$D$235,3,0) -> 3.649
B11: China | C11: CN | D11: 0.001 | E11: 0.001 | F11: 0.00189 | G11: 0.00189 | H11: 0.015 | I11: 0.0284 | J11: 0.000168 | K11: 0.00279 | L11: 0.000138 | M11: 0.00231 | N11: 2.19e-05 | O11: 0.000364 | P11: 0.000889 | Q11: 0.0148 | R11: 0.00168 | S11: 0.028 | T11: =SUM(D11:S11) -> 0.1003409 | V11: 0.0301 | W11: 0.0568 | X11: 0.00201 | Y11: 0.0334 | Z11: 0.00379 | AA11: 0.0631 | AB11: 0.241 | AC11: 0.455 | AD11: 0.00726 | AE11: 0.006 | AF11: 0.000947 | AG11: =SUM(V11:AF11) -> 0.899407 | AH11: =SUM(V11:AF11,D11:S11) -> 0.9997479 | AJ11: =VLOOKUP(C11,'extension - production vol'!$B$6:$D$235,3,0) -> 575.118
B12: Czech | C12: CZ | D12: 0.00216 | E12: 0.00216 | F12: 0.00408 | G12: 0.00408 | H12: 0.0324 | I12: 0.0612 | J12: 0.000833 | K12: 0.0139 | L12: 0.000688 | M12: 0.0115 | N12: 0.000109 | O12: 0.00181 | P12: 0.0016 | Q12: 0.0266 | R12: 0.00301 | S12: 0.0502 | T12: =SUM(D12:S12) -> 0.21633 | V12: 0.0648 | W12: 0.122 | X12: 0.00432 | Y12: 0.072 | Z12: 0.00816 | AA12: 0.136 | AB12: 0.124 | AC12: 0.235 | AD12: 0.00887 | AE12: 0.00733 | AF12: 0.00116 | AG12: =SUM(V12:AF12) -> 0.78364 | AH12: =SUM(V12:AF12,D12:S12) -> 0.99997 | AJ12: =VLOOKUP(C12,'extension - production vol'!$B$6:$D$235,3,0) -> 2892.093
B13: Denmark | C13: DK | D13: 0.00254 | E13: 0.00254 | F13: 0.0048 | G13: 0.0048 | H13: 0.0381 | I13: 0.0719 | J13: 0.000979 | K13: 0.0163 | L13: 0.000809 | M13: 0.0135 | N13: 0.000128 | O13: 0.00213 | P13: 0.00188 | Q13: 0.0313 | R13: 0.00354 | S13: 0.059 | T13: =SUM(D13:S13) -> 0.254246 | V13: 0.0762 | W13: 0.144 | X13: 0.00508 | Y13: 0.0847 | Z13: 0.00959 | AA13: 0.16 | AB13: 0.088 | AC13: 0.166 | AD13: 0.00629 | AE13: 0.00519 | AF13: 0.00082 | AG13: =SUM(V13:AF13) -> 0.74587 | AH13: =SUM(V13:AF13,D13:S13) -> 1.000116 | AJ13: =VLOOKUP(C13,'extension - production vol'!$B$6:$D$235,3,0) -> 3363.278
B14: Finland | C14: FI | D14: 0.00346 | E14: 0.00346 | F14: 0.00654 | G14: 0.00654 | H14: 0.0519 | I14: 0.0981 | J14: 0.00134 | K14: 0.0223 | L14: 0.0011 | M14: 0.0184 | N14: 0.000174 | O14: 0.0029 | P14: 0.00256 | Q14: 0.0426 | R14: 0.00483 | S14: 0.0805 | T14: =SUM(D14:S14) -> 0.346704 | V14: 0.104 | W14: 0.196 | X14: 0.00692 | Y14: 0.115 | Z14: 0.0131 | AA14: 0.218 | AB14: 0 | AC14: 0 | AD14: 0 | AE14: 0 | AF14: 0 | AG14: =SUM(V14:AF14) -> 0.65302 | AH14: =SUM(V14:AF14,D14:S14) -> 0.999724 | AJ14: =VLOOKUP(C14,'extension - production vol'!$B$6:$D$235,3,0) -> 716.44
B15: France | C15: FR | D15: 0.00207 | E15: 0.00207 | F15: 0.00391 | G15: 0.00391 | H15: 0.0311 | I15: 0.0587 | J15: 0.000799 | K15: 0.0133 | L15: 0.00066 | M15: 0.011 | N15: 0.000104 | O15: 0.00174 | P15: 0.00153 | Q15: 0.0255 | R15: 0.00289 | S15: 0.0481 | T15: =SUM(D15:S15) -> 0.207383 | V15: 0.0621 | W15: 0.117 | X15: 0.00414 | Y15: 0.069 | Z15: 0.00782 | AA15: 0.13 | AB15: 0.133 | AC15: 0.251 | AD15: 0.00948 | AE15: 0.00783 | AF15: 0.00124 | AG15: =SUM(V15:AF15) -> 0.79261 | AH15: =SUM(V15:AF15,D15:S15) -> 0.999993 | AJ15: =VLOOKUP(C15,'extension - production vol'!$B$6:$D$235,3,0) -> 302.606
B16: Germany | C16: DE | D16: 0.00258 | E16: 0.00258 | F16: 0.00487 | G16: 0.00487 | H16: 0.0387 | I16: 0.0731 | J16: 0.000995 | K16: 0.0166 | L16: 0.000822 | M16: 0.0137 | N16: 0.00013 | O16: 0.00216 | P16: 0.00191 | Q16: 0.0318 | R16: 0.0036 | S16: 0.06 | T16: =SUM(D16:S16) -> 0.258417 | V16: 0.0774 | W16: 0.146 | X16: 0.00516 | Y16: 0.086 | Z16: 0.00974 | AA16: 0.162 | AB16: 0.0841 | AC16: 0.159 | AD16: 0.00601 | AE16: 0.00496 | AF16: 0.000784 | AG16: =SUM(V16:AF16) -> 0.741154 | AH16: =SUM(V16:AF16,D16:S16) -> 0.999571 | AJ16: =VLOOKUP(C16,'extension - production vol'!$B$6:$D$235,3,0) -> 63576
B17: Greece | C17: GR | D17: 0.00216 | E17: 0.00216 | F17: 0.00408 | G17: 0.00408 | H17: 0.0324 | I17: 0.0612 | J17: 0.000833 | K17: 0.0139 | L17: 0.000688 | M17: 0.0115 | N17: 0.000109 | O17: 0.00181 | P17: 0.0016 | Q17: 0.0266 | R17: 0.00301 | S17: 0.0502 | T17: =SUM(D17:S17) -> 0.21633 | V17: 0.0648 | W17: 0.122 | X17: 0.00432 | Y17: 0.072 | Z17: 0.00816 | AA17: 0.136 | AB17: 0.124 | AC17: 0.235 | AD17: 0.00887 | AE17: 0.00733 | AF17: 0.00116 | AG17: =SUM(V17:AF17) -> 0.78364 | AH17: =SUM(V17:AF17,D17:S17) -> 0.99997 | AJ17: =VLOOKUP(C17,'extension - production vol'!$B$6:$D$235,3,0) -> 8893.572
... B38: USA | C38: US | D38: 0.00143 | E38: 0.00143 | F38: 0.00259 | G38: 0.00259 | H38: 0.0213 | I38: 0.0385 | J38: 5.77e-05 | K38: 0.00139 | L38: 0.000113 | M38: 0.00271 | N38: 7.72e-05 | O38: 0.00185 | P38: 0.000933 | Q38: 0.0224 | R38: 0.00168 | S38: 0.0404 | T38: =SUM(D38:S38) -> 0.1394509 | V38: 0.0427 | W38: 0.077 | X38: 0.00204 | Y38: 0.049 | Z38: 0.00368 | AA38: 0.0884 | AB38: 0.138 | AC38: 0.26 | AD38: 0.195 | AE38: 0.00506 | AF38: 0 | AG38: =SUM(V38:AF38) -> 0.86088 | AH38: =SUM(V38:AF38,D38:S38) -> 1.0003309 | AJ38: =VLOOKUP(C38,'extension - production vol'!$B$6:$D$235,3,0) -> 214436.07
B40: EXTENSION following the method of the IEA PVPS 2020 report, but WITHOUT technology split. Technology split derived as weighted average from data above.
B41: =VLOOKUP(C41,'extension - productivity'!A7:B182,2,0) -> Namibia | C41: NA | D41: =SUMPRODUCT(D$6:D$38,$AJ$6:$AJ$38)/SUM($AJ$6:$AJ$38) -> 0.0017325874 | E41: =SUMPRODUCT(E$6:E$38,$AJ$6:$AJ$38)/SUM($AJ$6:$AJ$38) -> 0.0017310882 | F41: =SUMPRODUCT(F$6:F$38,$AJ$6:$AJ$38)/SUM($AJ$6:$AJ$38) -> 0.0032864644 | G41: =SUMPRODUCT(G$6:G$38,$AJ$6:$AJ$38)/SUM($AJ$6:$AJ$38) -> 0.0032231518 | H41: =SUMPRODUCT(H$6:H$38,$AJ$6:$AJ$38)/SUM($AJ$6:$AJ$38) -> 0.026425553 | I41: =SUMPRODUCT(I$6:I$38,$AJ$6:$AJ$38)/SUM($AJ$6:$AJ$38) -> 0.05062507 | J41: =SUMPRODUCT(J$6:J$38,$AJ$6:$AJ$38)/SUM($AJ$6:$AJ$38) -> 0.00040926991 | K41: =SUMPRODUCT(K$6:K$38,$AJ$6:$AJ$38)/SUM($AJ$6:$AJ$38) -> 0.0059328609 | ... S41: =SUMPRODUCT(S$6:S$38,$AJ$6:$AJ$38)/SUM($AJ$6:$AJ$38) -> 0.041618585 | T41: =SUMPRODUCT($T$6:$T$38,$AJ$6:$AJ$38)/SUM($AJ$6:$AJ$38) -> 0.17766752 | V41: =SUMPRODUCT(V$6:V$38,$AJ$6:$AJ$38)/SUM($AJ$6:$AJ$38) -> 0.052740019 | W41: =SUMPRODUCT(W$6:W$38,$AJ$6:$AJ$38)/SUM($AJ$6:$AJ$38) -> 0.10096416 | X41: =SUMPRODUCT(X$6:X$38,$AJ$6:$AJ$38)/SUM($AJ$6:$AJ$38) -> 0.0034940466 | Y41: =SUMPRODUCT(Y$6:Y$38,$AJ$6:$AJ$38)/SUM($AJ$6:$AJ$38) -> 0.05870501 | Z41: =SUMPRODUCT(Z$6:Z$38,$AJ$6:$AJ$38)/SUM($AJ$6:$AJ$38) -> 0.0066094595 | AA41: =SUMPRODUCT(AA$6:AA$38,$AJ$6:$AJ$38)/SUM($AJ$6:$AJ$38) -> 0.11207299 | AB41: =SUMPRODUCT(AB$6:AB$38,$AJ$6:$AJ$38)/SUM($AJ$6:$AJ$38) -> 0.13965389 | AC41: =SUMPRODUCT(AC$6:AC$38,$AJ$6:$AJ$38)/SUM($AJ$6:$AJ$38) -> 0.26327782 | ... AF41: =SUMPRODUCT(AF$6:AF$38,$AJ$6:$AJ$38)/SUM($AJ$6:$AJ$38) -> 0.00078672777 | AG41: =1-T41 -> 0.82233248
B42: =VLOOKUP(C42,'extension - productivity'!A8:B183,2,0) -> Egypt | C42: EG | D42: =SUMPRODUCT(D$6:D$38,$AJ$6:$AJ$38)/SUM($AJ$6:$AJ$38) -> 0.0017325874 | E42: =SUMPRODUCT(E$6:E$38,$AJ$6:$AJ$38)/SUM($AJ$6:$AJ$38) -> 0.0017310882 | F42: =SUMPRODUCT(F$6:F$38,$AJ$6:$AJ$38)/SUM($AJ$6:$AJ$38) -> 0.0032864644 | G42: =SUMPRODUCT(G$6:G$38,$AJ$6:$AJ$38)/SUM($AJ$6:$AJ$38) -> 0.0032231518 | H42: =SUMPRODUCT(H$6:H$38,$AJ$6:$AJ$38)/SUM($AJ$6:$AJ$38) -> 0.026425553 | I42: =SUMPRODUCT(I$6:I$38,$AJ$6:$AJ$38)/SUM($AJ$6:$AJ$38) -> 0.05062507 | J42: =SUMPRODUCT(J$6:J$38,$AJ$6:$AJ$38)/SUM($AJ$6:$AJ$38) -> 0.00040926991 | K42: =SUMPRODUCT(K$6:K$38,$AJ$6:$AJ$38)/SUM($AJ$6:$AJ$38) -> 0.0059328609 | ... S42: =SUMPRODUCT(S$6:S$38,$AJ$6:$AJ$38)/SUM($AJ$6:$AJ$38) -> 0.041618585 | T42: =SUMPRODUCT($T$6:$T$38,$AJ$6:$AJ$38)/SUM($AJ$6:$AJ$38) -> 0.17766752 | V42: =SUMPRODUCT(V$6:V$38,$AJ$6:$AJ$38)/SUM($AJ$6:$AJ$38) -> 0.052740019 | W42: =SUMPRODUCT(W$6:W$38,$AJ$6:$AJ$38)/SUM($AJ$6:$AJ$38) -> 0.10096416 | X42: =SUMPRODUCT(X$6:X$38,$AJ$6:$AJ$38)/SUM($AJ$6:$AJ$38) -> 0.0034940466 | Y42: =SUMPRODUCT(Y$6:Y$38,$AJ$6:$AJ$38)/SUM($AJ$6:$AJ$38) -> 0.05870501 | Z42: =SUMPRODUCT(Z$6:Z$38,$AJ$6:$AJ$38)/SUM($AJ$6:$AJ$38) -> 0.0066094595 | AA42: =SUMPRODUCT(AA$6:AA$38,$AJ$6:$AJ$38)/SUM($AJ$6:$AJ$38) -> 0.11207299 | AB42: =SUMPRODUCT(AB$6:AB$38,$AJ$6:$AJ$38)/SUM($AJ$6:$AJ$38) -> 0.13965389 | AC42: =SUMPRODUCT(AC$6:AC$38,$AJ$6:$AJ$38)/SUM($AJ$6:$AJ$38) -> 0.26327782 | ... AF42: =SUMPRODUCT(AF$6:AF$38,$AJ$6:$AJ$38)/SUM($AJ$6:$AJ$38) -> 0.00078672777 | AG42: =1-T42 -> 0.82233248
B43: =VLOOKUP(C43,'extension - productivity'!A9:B184,2,0) -> Jordan | C43: JO | D43: =SUMPRODUCT(D$6:D$38,$AJ$6:$AJ$38)/SUM($AJ$6:$AJ$38) -> 0.0017325874 | E43: =SUMPRODUCT(E$6:E$38,$AJ$6:$AJ$38)/SUM($AJ$6:$AJ$38) -> 0.0017310882 | F43: =SUMPRODUCT(F$6:F$38,$AJ$6:$AJ$38)/SUM($AJ$6:$AJ$38) -> 0.0032864644 | G43: =SUMPRODUCT(G$6:G$38,$AJ$6:$AJ$38)/SUM($AJ$6:$AJ$38) -> 0.0032231518 | H43: =SUMPRODUCT(H$6:H$38,$AJ$6:$AJ$38)/SUM($AJ$6:$AJ$38) -> 0.026425553 | I43: =SUMPRODUCT(I$6:I$38,$AJ$6:$AJ$38)/SUM($AJ$6:$AJ$38) -> 0.05062507 | J43: =SUMPRODUCT(J$6:J$38,$AJ$6:$AJ$38)/SUM($AJ$6:$AJ$38) -> 0.00040926991 | K43: =SUMPRODUCT(K$6:K$38,$AJ$6:$AJ$38)/SUM($AJ$6:$AJ$38) -> 0.0059328609 | ... S43: =SUMPRODUCT(S$6:S$38,$AJ$6:$AJ$38)/SUM($AJ$6:$AJ$38) -> 0.041618585 | T43: =SUMPRODUCT($T$6:$T$38,$AJ$6:$AJ$38)/SUM($AJ$6:$AJ$38) -> 0.17766752 | V43: =SUMPRODUCT(V$6:V$38,$AJ$6:$AJ$38)/SUM($AJ$6:$AJ$38) -> 0.052740019 | W43: =SUMPRODUCT(W$6:W$38,$AJ$6:$AJ$38)/SUM($AJ$6:$AJ$38) -> 0.10096416 | X43: =SUMPRODUCT(X$6:X$38,$AJ$6:$AJ$38)/SUM($AJ$6:$AJ$38) -> 0.0034940466 | Y43: =SUMPRODUCT(Y$6:Y$38,$AJ$6:$AJ$38)/SUM($AJ$6:$AJ$38) -> 0.05870501 | Z43: =SUMPRODUCT(Z$6:Z$38,$AJ$6:$AJ$38)/SUM($AJ$6:$AJ$38) -> 0.0066094595 | AA43: =SUMPRODUCT(AA$6:AA$38,$AJ$6:$AJ$38)/SUM($AJ$6:$AJ$38) -> 0.11207299 | AB43: =SUMPRODUCT(AB$6:AB$38,$AJ$6:$AJ$38)/SUM($AJ$6:$AJ$38) -> 0.13965389 | AC43: =SUMPRODUCT(AC$6:AC$38,$AJ$6:$AJ$38)/SUM($AJ$6:$AJ$38) -> 0.26327782 | ... AF43: =SUMPRODUCT(AF$6:AF$38,$AJ$6:$AJ$38)/SUM($AJ$6:$AJ$38) -> 0.00078672777 | AG43: =1-T43 -> 0.82233248
B44: =VLOOKUP(C44,'extension - productivity'!A10:B185,2,0) -> Libya | C44: LY | D44: =SUMPRODUCT(D$6:D$38,$AJ$6:$AJ$38)/SUM($AJ$6:$AJ$38) -> 0.0017325874 | E44: =SUMPRODUCT(E$6:E$38,$AJ$6:$AJ$38)/SUM($AJ$6:$AJ$38) -> 0.0017310882 | F44: =SUMPRODUCT(F$6:F$38,$AJ$6:$AJ$38)/SUM($AJ$6:$AJ$38) -> 0.0032864644 | G44: =SUMPRODUCT(G$6:G$38,$AJ$6:$AJ$38)/SUM($AJ$6:$AJ$38) -> 0.0032231518 | H44: =SUMPRODUCT(H$6:H$38,$AJ$6:$AJ$38)/SUM($AJ$6:$AJ$38) -> 0.026425553 | I44: =SUMPRODUCT(I$6:I$38,$AJ$6:$AJ$38)/SUM($AJ$6:$AJ$38) -> 0.05062507 | J44: =SUMPRODUCT(J$6:J$38,$AJ$6:$AJ$38)/SUM($AJ$6:$AJ$38) -> 0.00040926991 | K44: =SUMPRODUCT(K$6:K$38,$AJ$6:$AJ$38)/SUM($AJ$6:$AJ$38) -> 0.0059328609 | ... S44: =SUMPRODUCT(S$6:S$38,$AJ$6:$AJ$38)/SUM($AJ$6:$AJ$38) -> 0.041618585 | T44: =SUMPRODUCT($T$6:$T$38,$AJ$6:$AJ$38)/SUM($AJ$6:$AJ$38) -> 0.17766752 | V44: =SUMPRODUCT(V$6:V$38,$AJ$6:$AJ$38)/SUM($AJ$6:$AJ$38) -> 0.052740019 | W44: =SUMPRODUCT(W$6:W$38,$AJ$6:$AJ$38)/SUM($AJ$6:$AJ$38) -> 0.10096416 | X44: =SUMPRODUCT(X$6:X$38,$AJ$6:$AJ$38)/SUM($AJ$6:$AJ$38) -> 0.0034940466 | Y44: =SUMPRODUCT(Y$6:Y$38,$AJ$6:$AJ$38)/SUM($AJ$6:$AJ$38) -> 0.05870501 | Z44: =SUMPRODUCT(Z$6:Z$38,$AJ$6:$AJ$38)/SUM($AJ$6:$AJ$38) -> 0.0066094595 | AA44: =SUMPRODUCT(AA$6:AA$38,$AJ$6:$AJ$38)/SUM($AJ$6:$AJ$38) -> 0.11207299 | AB44: =SUMPRODUCT(AB$6:AB$38,$AJ$6:$AJ$38)/SUM($AJ$6:$AJ$38) -> 0.13965389 | AC44: =SUMPRODUCT(AC$6:AC$38,$AJ$6:$AJ$38)/SUM($AJ$6:$AJ$38) -> 0.26327782 | ... AF44: =SUMPRODUCT(AF$6:AF$38,$AJ$6:$AJ$38)/SUM($AJ$6:$AJ$38) -> 0.00078672777 | AG44: =1-T44 -> 0.82233248
B45: =VLOOKUP(C45,'extension - productivity'!A11:B186,2,0) -> Yemen | C45: YE | D45: =SUMPRODUCT(D$6:D$38,$AJ$6:$AJ$38)/SUM($AJ$6:$AJ$38) -> 0.0017325874 | E45: =SUMPRODUCT(E$6:E$38,$AJ$6:$AJ$38)/SUM($AJ$6:$AJ$38) -> 0.0017310882 | F45: =SUMPRODUCT(F$6:F$38,$AJ$6:$AJ$38)/SUM($AJ$6:$AJ$38) -> 0.0032864644 | G45: =SUMPRODUCT(G$6:G$38,$AJ$6:$AJ$38)/SUM($AJ$6:$AJ$38) -> 0.0032231518 | H45: =SUMPRODUCT(H$6:H$38,$AJ$6:$AJ$38)/SUM($AJ$6:$AJ$38) -> 0.026425553 | I45: =SUMPRODUCT(I$6:I$38,$AJ$6:$AJ$38)/SUM($AJ$6:$AJ$38) -> 0.05062507 | J45: =SUMPRODUCT(J$6:J$38,$AJ$6:$AJ$38)/SUM($AJ$6:$AJ$38) -> 0.00040926991 | K45: =SUMPRODUCT(K$6:K$38,$AJ$6:$AJ$38)/SUM($AJ$6:$AJ$38) -> 0.0059328609 | ... S45: =SUMPRODUCT(S$6:S$38,$AJ$6:$AJ$38)/SUM($AJ$6:$AJ$38) -> 0.041618585 | T45: =SUMPRODUCT($T$6:$T$38,$AJ$6:$AJ$38)/SUM($AJ$6:$AJ$38) -> 0.17766752 | V45: =SUMPRODUCT(V$6:V$38,$AJ$6:$AJ$38)/SUM($AJ$6:$AJ$38) -> 0.052740019 | W45: =SUMPRODUCT(W$6:W$38,$AJ$6:$AJ$38)/SUM($AJ$6:$AJ$38) -> 0.10096416 | X45: =SUMPRODUCT(X$6:X$38,$AJ$6:$AJ$38)/SUM($AJ$6:$AJ$38) -> 0.0034940466 | Y45: =SUMPRODUCT(Y$6:Y$38,$AJ$6:$AJ$38)/SUM($AJ$6:$AJ$38) -> 0.05870501 | Z45: =SUMPRODUCT(Z$6:Z$38,$AJ$6:$AJ$38)/SUM($AJ$6:$AJ$38) -> 0.0066094595 | AA45: =SUMPRODUCT(AA$6:AA$38,$AJ$6:$AJ$38)/SUM($AJ$6:$AJ$38) -> 0.11207299 | AB45: =SUMPRODUCT(AB$6:AB$38,$AJ$6:$AJ$38)/SUM($AJ$6:$AJ$38) -> 0.13965389 | AC45: =SUMPRODUCT(AC$6:AC$38,$AJ$6:$AJ$38)/SUM($AJ$6:$AJ$38) -> 0.26327782 | ... AF45: =SUMPRODUCT(AF$6:AF$38,$AJ$6:$AJ$38)/SUM($AJ$6:$AJ$38) -> 0.00078672777 | AG45: =1-T45 -> 0.82233248
B46: =VLOOKUP(C46,'extension - productivity'!A12:B187,2,0) -> Saudi Arabia | C46: SA | D46: =SUMPRODUCT(D$6:D$38,$AJ$6:$AJ$38)/SUM($AJ$6:$AJ$38) -> 0.0017325874 | E46: =SUMPRODUCT(E$6:E$38,$AJ$6:$AJ$38)/SUM($AJ$6:$AJ$38) -> 0.0017310882 | F46: =SUMPRODUCT(F$6:F$38,$AJ$6:$AJ$38)/SUM($AJ$6:$AJ$38) -> 0.0032864644 | G46: =SUMPRODUCT(G$6:G$38,$AJ$6:$AJ$38)/SUM($AJ$6:$AJ$38) -> 0.0032231518 | H46: =SUMPRODUCT(H$6:H$38,$AJ$6:$AJ$38)/SUM($AJ$6:$AJ$38) -> 0.026425553 | I46: =SUMPRODUCT(I$6:I$38,$AJ$6:$AJ$38)/SUM($AJ$6:$AJ$38) -> 0.05062507 | J46: =SUMPRODUCT(J$6:J$38,$AJ$6:$AJ$38)/SUM($AJ$6:$AJ$38) -> 0.00040926991 | K46: =SUMPRODUCT(K$6:K$38,$AJ$6:$AJ$38)/SUM($AJ$6:$AJ$38) -> 0.0059328609 | ... S46: =SUMPRODUCT(S$6:S$38,$AJ$6:$AJ$38)/SUM($AJ$6:$AJ$38) -> 0.041618585 | T46: =SUMPRODUCT($T$6:$T$38,$AJ$6:$AJ$38)/SUM($AJ$6:$AJ$38) -> 0.17766752 | V46: =SUMPRODUCT(V$6:V$38,$AJ$6:$AJ$38)/SUM($AJ$6:$AJ$38) -> 0.052740019 | W46: =SUMPRODUCT(W$6:W$38,$AJ$6:$AJ$38)/SUM($AJ$6:$AJ$38) -> 0.10096416 | X46: =SUMPRODUCT(X$6:X$38,$AJ$6:$AJ$38)/SUM($AJ$6:$AJ$38) -> 0.0034940466 | Y46: =SUMPRODUCT(Y$6:Y$38,$AJ$6:$AJ$38)/SUM($AJ$6:$AJ$38) -> 0.05870501 | Z46: =SUMPRODUCT(Z$6:Z$38,$AJ$6:$AJ$38)/SUM($AJ$6:$AJ$38) -> 0.0066094595 | AA46: =SUMPRODUCT(AA$6:AA$38,$AJ$6:$AJ$38)/SUM($AJ$6:$AJ$38) -> 0.11207299 | AB46: =SUMPRODUCT(AB$6:AB$38,$AJ$6:$AJ$38)/SUM($AJ$6:$AJ$38) -> 0.13965389 | AC46: =SUMPRODUCT(AC$6:AC$38,$AJ$6:$AJ$38)/SUM($AJ$6:$AJ$38) -> 0.26327782 | ... AF46: =SUMPRODUCT(AF$6:AF$38,$AJ$6:$AJ$38)/SUM($AJ$6:$AJ$38) -> 0.00078672777 | AG46: =1-T46 -> 0.82233248
B47: =VLOOKUP(C47,'extension - productivity'!A13:B188,2,0) -> Western Sahara | C47: EH | D47: =SUMPRODUCT(D$6:D$38,$AJ$6:$AJ$38)/SUM($AJ$6:$AJ$38) -> 0.0017325874 | E47: =SUMPRODUCT(E$6:E$38,$AJ$6:$AJ$38)/SUM($AJ$6:$AJ$38) -> 0.0017310882 | F47: =SUMPRODUCT(F$6:F$38,$AJ$6:$AJ$38)/SUM($AJ$6:$AJ$38) -> 0.0032864644 | G47: =SUMPRODUCT(G$6:G$38,$AJ$6:$AJ$38)/SUM($AJ$6:$AJ$38) -> 0.0032231518 | H47: =SUMPRODUCT(H$6:H$38,$AJ$6:$AJ$38)/SUM($AJ$6:$AJ$38) -> 0.026425553 | I47: =SUMPRODUCT(I$6:I$38,$AJ$6:$AJ$38)/SUM($AJ$6:$AJ$38) -> 0.05062507 | J47: =SUMPRODUCT(J$6:J$38,$AJ$6:$AJ$38)/SUM($AJ$6:$AJ$38) -> 0.00040926991 | K47: =SUMPRODUCT(K$6:K$38,$AJ$6:$AJ$38)/SUM($AJ$6:$AJ$38) -> 0.0059328609 | ... S47: =SUMPRODUCT(S$6:S$38,$AJ$6:$AJ$38)/SUM($AJ$6:$AJ$38) -> 0.041618585 | T47: =SUMPRODUCT($T$6:$T$38,$AJ$6:$AJ$38)/SUM($AJ$6:$AJ$38) -> 0.17766752 | V47: =SUMPRODUCT(V$6:V$38,$AJ$6:$AJ$38)/SUM($AJ$6:$AJ$38) -> 0.052740019 | W47: =SUMPRODUCT(W$6:W$38,$AJ$6:$AJ$38)/SUM($AJ$6:$AJ$38) -> 0.10096416 | X47: =SUMPRODUCT(X$6:X$38,$AJ$6:$AJ$38)/SUM($AJ$6:$AJ$38) -> 0.0034940466 | Y47: =SUMPRODUCT(Y$6:Y$38,$AJ$6:$AJ$38)/SUM($AJ$6:$AJ$38) -> 0.05870501 | Z47: =SUMPRODUCT(Z$6:Z$38,$AJ$6:$AJ$38)/SUM($AJ$6:$AJ$38) -> 0.0066094595 | AA47: =SUMPRODUCT(AA$6:AA$38,$AJ$6:$AJ$38)/SUM($AJ$6:$AJ$38) -> 0.11207299 | AB47: =SUMPRODUCT(AB$6:AB$38,$AJ$6:$AJ$38)/SUM($AJ$6:$AJ$38) -> 0.13965389 | AC47: =SUMPRODUCT(AC$6:AC$38,$AJ$6:$AJ$38)/SUM($AJ$6:$AJ$38) -> 0.26327782 | ... AF47: =SUMPRODUCT(AF$6:AF$38,$AJ$6:$AJ$38)/SUM($AJ$6:$AJ$38) -> 0.00078672777 | AG47: =1-T47 -> 0.82233248
B48: =VLOOKUP(C48,'extension - productivity'!A14:B189,2,0) -> Botswana | C48: BW | D48: =SUMPRODUCT(D$6:D$38,$AJ$6:$AJ$38)/SUM($AJ$6:$AJ$38) -> 0.0017325874 | E48: =SUMPRODUCT(E$6:E$38,$AJ$6:$AJ$38)/SUM($AJ$6:$AJ$38) -> 0.0017310882 | F48: =SUMPRODUCT(F$6:F$38,$AJ$6:$AJ$38)/SUM($AJ$6:$AJ$38) -> 0.0032864644 | G48: =SUMPRODUCT(G$6:G$38,$AJ$6:$AJ$38)/SUM($AJ$6:$AJ$38) -> 0.0032231518 | H48: =SUMPRODUCT(H$6:H$38,$AJ$6:$AJ$38)/SUM($AJ$6:$AJ$38) -> 0.026425553 | I48: =SUMPRODUCT(I$6:I$38,$AJ$6:$AJ$38)/SUM($AJ$6:$AJ$38) -> 0.05062507 | J48: =SUMPRODUCT(J$6:J$38,$AJ$6:$AJ$38)/SUM($AJ$6:$AJ$38) -> 0.00040926991 | K48: =SUMPRODUCT(K$6:K$38,$AJ$6:$AJ$38)/SUM($AJ$6:$AJ$38) -> 0.0059328609 | ... S48: =SUMPRODUCT(S$6:S$38,$AJ$6:$AJ$38)/SUM($AJ$6:$AJ$38) -> 0.041618585 | T48: =SUMPRODUCT($T$6:$T$38,$AJ$6:$AJ$38)/SUM($AJ$6:$AJ$38) -> 0.17766752 | V48: =SUMPRODUCT(V$6:V$38,$AJ$6:$AJ$38)/SUM($AJ$6:$AJ$38) -> 0.052740019 | W48: =SUMPRODUCT(W$6:W$38,$AJ$6:$AJ$38)/SUM($AJ$6:$AJ$38) -> 0.10096416 | X48: =SUMPRODUCT(X$6:X$38,$AJ$6:$AJ$38)/SUM($AJ$6:$AJ$38) -> 0.0034940466 | Y48: =SUMPRODUCT(Y$6:Y$38,$AJ$6:$AJ$38)/SUM($AJ$6:$AJ$38) -> 0.05870501 | Z48: =SUMPRODUCT(Z$6:Z$38,$AJ$6:$AJ$38)/SUM($AJ$6:$AJ$38) -> 0.0066094595 | AA48: =SUMPRODUCT(AA$6:AA$38,$AJ$6:$AJ$38)/SUM($AJ$6:$AJ$38) -> 0.11207299 | AB48: =SUMPRODUCT(AB$6:AB$38,$AJ$6:$AJ$38)/SUM($AJ$6:$AJ$38) -> 0.13965389 | AC48: =SUMPRODUCT(AC$6:AC$38,$AJ$6:$AJ$38)/SUM($AJ$6:$AJ$38) -> 0.26327782 | ... AF48: =SUMPRODUCT(AF$6:AF$38,$AJ$6:$AJ$38)/SUM($AJ$6:$AJ$38) -> 0.00078672777 | AG48: =1-T48 -> 0.82233248
B49: =VLOOKUP(C49,'extension - productivity'!A15:B190,2,0) -> Oman | C49: OM | D49: =SUMPRODUCT(D$6:D$38,$AJ$6:$AJ$38)/SUM($AJ$6:$AJ$38) -> 0.0017325874 | E49: =SUMPRODUCT(E$6:E$38,$AJ$6:$AJ$38)/SUM($AJ$6:$AJ$38) -> 0.0017310882 | F49: =SUMPRODUCT(F$6:F$38,$AJ$6:$AJ$38)/SUM($AJ$6:$AJ$38) -> 0.0032864644 | G49: =SUMPRODUCT(G$6:G$38,$AJ$6:$AJ$38)/SUM($AJ$6:$AJ$38) -> 0.0032231518 | H49: =SUMPRODUCT(H$6:H$38,$AJ$6:$AJ$38)/SUM($AJ$6:$AJ$38) -> 0.026425553 | I49: =SUMPRODUCT(I$6:I$38,$AJ$6:$AJ$38)/SUM($AJ$6:$AJ$38) -> 0.05062507 | J49: =SUMPRODUCT(J$6:J$38,$AJ$6:$AJ$38)/SUM($AJ$6:$AJ$38) -> 0.00040926991 | K49: =SUMPRODUCT(K$6:K$38,$AJ$6:$AJ$38)/SUM($AJ$6:$AJ$38) -> 0.0059328609 | ... S49: =SUMPRODUCT(S$6:S$38,$AJ$6:$AJ$38)/SUM($AJ$6:$AJ$38) -> 0.041618585 | T49: =SUMPRODUCT($T$6:$T$38,$AJ$6:$AJ$38)/SUM($AJ$6:$AJ$38) -> 0.17766752 | V49: =SUMPRODUCT(V$6:V$38,$AJ$6:$AJ$38)/SUM($AJ$6:$AJ$38) -> 0.052740019 | W49: =SUMPRODUCT(W$6:W$38,$AJ$6:$AJ$38)/SUM($AJ$6:$AJ$38) -> 0.10096416 | X49: =SUMPRODUCT(X$6:X$38,$AJ$6:$AJ$38)/SUM($AJ$6:$AJ$38) -> 0.0034940466 | Y49: =SUMPRODUCT(Y$6:Y$38,$AJ$6:$AJ$38)/SUM($AJ$6:$AJ$38) -> 0.05870501 | Z49: =SUMPRODUCT(Z$6:Z$38,$AJ$6:$AJ$38)/SUM($AJ$6:$AJ$38) -> 0.0066094595 | AA49: =SUMPRODUCT(AA$6:AA$38,$AJ$6:$AJ$38)/SUM($AJ$6:$AJ$38) -> 0.11207299 | AB49: =SUMPRODUCT(AB$6:AB$38,$AJ$6:$AJ$38)/SUM($AJ$6:$AJ$38) -> 0.13965389 | AC49: =SUMPRODUCT(AC$6:AC$38,$AJ$6:$AJ$38)/SUM($AJ$6:$AJ$38) -> 0.26327782 | ... AF49: =SUMPRODUCT(AF$6:AF$38,$AJ$6:$AJ$38)/SUM($AJ$6:$AJ$38) -> 0.00078672777 | AG49: =1-T49 -> 0.82233248
B50: =VLOOKUP(C50,'extension - productivity'!A16:B191,2,0) -> Algeria | C50: DZ | D50: =SUMPRODUCT(D$6:D$38,$AJ$6:$AJ$38)/SUM($AJ$6:$AJ$38) -> 0.0017325874 | E50: =SUMPRODUCT(E$6:E$38,$AJ$6:$AJ$38)/SUM($AJ$6:$AJ$38) -> 0.0017310882 | F50: =SUMPRODUCT(F$6:F$38,$AJ$6:$AJ$38)/SUM($AJ$6:$AJ$38) -> 0.0032864644 | G50: =SUMPRODUCT(G$6:G$38,$AJ$6:$AJ$38)/SUM($AJ$6:$AJ$38) -> 0.0032231518 | H50: =SUMPRODUCT(H$6:H$38,$AJ$6:$AJ$38)/SUM($AJ$6:$AJ$38) -> 0.026425553 | I50: =SUMPRODUCT(I$6:I$38,$AJ$6:$AJ$38)/SUM($AJ$6:$AJ$38) -> 0.05062507 | J50: =SUMPRODUCT(J$6:J$38,$AJ$6:$AJ$38)/SUM($AJ$6:$AJ$38) -> 0.00040926991 | K50: =SUMPRODUCT(K$6:K$38,$AJ$6:$AJ$38)/SUM($AJ$6:$AJ$38) -> 0.0059328609 | ... S50: =SUMPRODUCT(S$6:S$38,$AJ$6:$AJ$38)/SUM($AJ$6:$AJ$38) -> 0.041618585 | T50: =SUMPRODUCT($T$6:$T$38,$AJ$6:$AJ$38)/SUM($AJ$6:$AJ$38) -> 0.17766752 | V50: =SUMPRODUCT(V$6:V$38,$AJ$6:$AJ$38)/SUM($AJ$6:$AJ$38) -> 0.052740019 | W50: =SUMPRODUCT(W$6:W$38,$AJ$6:$AJ$38)/SUM($AJ$6:$AJ$38) -> 0.10096416 | X50: =SUMPRODUCT(X$6:X$38,$AJ$6:$AJ$38)/SUM($AJ$6:$AJ$38) -> 0.0034940466 | Y50: =SUMPRODUCT(Y$6:Y$38,$AJ$6:$AJ$38)/SUM($AJ$6:$AJ$38) -> 0.05870501 | Z50: =SUMPRODUCT(Z$6:Z$38,$AJ$6:$AJ$38)/SUM($AJ$6:$AJ$38) -> 0.0066094595 | AA50: =SUMPRODUCT(AA$6:AA$38,$AJ$6:$AJ$38)/SUM($AJ$6:$AJ$38) -> 0.11207299 | AB50: =SUMPRODUCT(AB$6:AB$38,$AJ$6:$AJ$38)/SUM($AJ$6:$AJ$38) -> 0.13965389 | AC50: =SUMPRODUCT(AC$6:AC$38,$AJ$6:$AJ$38)/SUM($AJ$6:$AJ$38) -> 0.26327782 | ... AF50: =SUMPRODUCT(AF$6:AF$38,$AJ$6:$AJ$38)/SUM($AJ$6:$AJ$38) -> 0.00078672777 | AG50: =1-T50 -> 0.82233248
B51: =VLOOKUP(C51,'extension - productivity'!A17:B192,2,0) -> Sudan | C51: SD | D51: =SUMPRODUCT(D$6:D$38,$AJ$6:$AJ$38)/SUM($AJ$6:$AJ$38) -> 0.0017325874 | E51: =SUMPRODUCT(E$6:E$38,$AJ$6:$AJ$38)/SUM($AJ$6:$AJ$38) -> 0.0017310882 | F51: =SUMPRODUCT(F$6:F$38,$AJ$6:$AJ$38)/SUM($AJ$6:$AJ$38) -> 0.0032864644 | G51: =SUMPRODUCT(G$6:G$38,$AJ$6:$AJ$38)/SUM($AJ$6:$AJ$38) -> 0.0032231518 | H51: =SUMPRODUCT(H$6:H$38,$AJ$6:$AJ$38)/SUM($AJ$6:$AJ$38) -> 0.026425553 | I51: =SUMPRODUCT(I$6:I$38,$AJ$6:$AJ$38)/SUM($AJ$6:$AJ$38) -> 0.05062507 | J51: =SUMPRODUCT(J$6:J$38,$AJ$6:$AJ$38)/SUM($AJ$6:$AJ$38) -> 0.00040926991 | K51: =SUMPRODUCT(K$6:K$38,$AJ$6:$AJ$38)/SUM($AJ$6:$AJ$38) -> 0.0059328609 | ... S51: =SUMPRODUCT(S$6:S$38,$AJ$6:$AJ$38)/SUM($AJ$6:$AJ$38) -> 0.041618585 | T51: =SUMPRODUCT($T$6:$T$38,$AJ$6:$AJ$38)/SUM($AJ$6:$AJ$38) -> 0.17766752 | V51: =SUMPRODUCT(V$6:V$38,$AJ$6:$AJ$38)/SUM($AJ$6:$AJ$38) -> 0.052740019 | W51: =SUMPRODUCT(W$6:W$38,$AJ$6:$AJ$38)/SUM($AJ$6:$AJ$38) -> 0.10096416 | X51: =SUMPRODUCT(X$6:X$38,$AJ$6:$AJ$38)/SUM($AJ$6:$AJ$38) -> 0.0034940466 | Y51: =SUMPRODUCT(Y$6:Y$38,$AJ$6:$AJ$38)/SUM($AJ$6:$AJ$38) -> 0.05870501 | Z51: =SUMPRODUCT(Z$6:Z$38,$AJ$6:$AJ$38)/SUM($AJ$6:$AJ$38) -> 0.0066094595 | AA51: =SUMPRODUCT(AA$6:AA$38,$AJ$6:$AJ$38)/SUM($AJ$6:$AJ$38) -> 0.11207299 | AB51: =SUMPRODUCT(AB$6:AB$38,$AJ$6:$AJ$38)/SUM($AJ$6:$AJ$38) -> 0.13965389 | AC51: =SUMPRODUCT(AC$6:AC$38,$AJ$6:$AJ$38)/SUM($AJ$6:$AJ$38) -> 0.26327782 | ... AF51: =SUMPRODUCT(AF$6:AF$38,$AJ$6:$AJ$38)/SUM($AJ$6:$AJ$38) -> 0.00078672777 | AG51: =1-T51 -> 0.82233248
B52: =VLOOKUP(C52,'extension - productivity'!A18:B193,2,0) -> Lesotho | C52: LS | D52: =SUMPRODUCT(D$6:D$38,$AJ$6:$AJ$38)/SUM($AJ$6:$AJ$38) -> 0.0017325874 | E52: =SUMPRODUCT(E$6:E$38,$AJ$6:$AJ$38)/SUM($AJ$6:$AJ$38) -> 0.0017310882 | F52: =SUMPRODUCT(F$6:F$38,$AJ$6:$AJ$38)/SUM($AJ$6:$AJ$38) -> 0.0032864644 | G52: =SUMPRODUCT(G$6:G$38,$AJ$6:$AJ$38)/SUM($AJ$6:$AJ$38) -> 0.0032231518 | H52: =SUMPRODUCT(H$6:H$38,$AJ$6:$AJ$38)/SUM($AJ$6:$AJ$38) -> 0.026425553 | I52: =SUMPRODUCT(I$6:I$38,$AJ$6:$AJ$38)/SUM($AJ$6:$AJ$38) -> 0.05062507 | J52: =SUMPRODUCT(J$6:J$38,$AJ$6:$AJ$38)/SUM($AJ$6:$AJ$38) -> 0.00040926991 | K52: =SUMPRODUCT(K$6:K$38,$AJ$6:$AJ$38)/SUM($AJ$6:$AJ$38) -> 0.0059328609 | ... S52: =SUMPRODUCT(S$6:S$38,$AJ$6:$AJ$38)/SUM($AJ$6:$AJ$38) -> 0.041618585 | T52: =SUMPRODUCT($T$6:$T$38,$AJ$6:$AJ$38)/SUM($AJ$6:$AJ$38) -> 0.17766752 | V52: =SUMPRODUCT(V$6:V$38,$AJ$6:$AJ$38)/SUM($AJ$6:$AJ$38) -> 0.052740019 | W52: =SUMPRODUCT(W$6:W$38,$AJ$6:$AJ$38)/SUM($AJ$6:$AJ$38) -> 0.10096416 | X52: =SUMPRODUCT(X$6:X$38,$AJ$6:$AJ$38)/SUM($AJ$6:$AJ$38) -> 0.0034940466 | Y52: =SUMPRODUCT(Y$6:Y$38,$AJ$6:$AJ$38)/SUM($AJ$6:$AJ$38) -> 0.05870501 | Z52: =SUMPRODUCT(Z$6:Z$38,$AJ$6:$AJ$38)/SUM($AJ$6:$AJ$38) -> 0.0066094595 | AA52: =SUMPRODUCT(AA$6:AA$38,$AJ$6:$AJ$38)/SUM($AJ$6:$AJ$38) -> 0.11207299 | AB52: =SUMPRODUCT(AB$6:AB$38,$AJ$6:$AJ$38)/SUM($AJ$6:$AJ$38) -> 0.13965389 | AC52: =SUMPRODUCT(AC$6:AC$38,$AJ$6:$AJ$38)/SUM($AJ$6:$AJ$38) -> 0.26327782 | ... AF52: =SUMPRODUCT(AF$6:AF$38,$AJ$6:$AJ$38)/SUM($AJ$6:$AJ$38) -> 0.00078672777 | AG52: =1-T52 -> 0.82233248
