Workbook

Sheet unallocated
A1: skip
A3: Activity | B3: municipal waste incineration, at incineration plant, with semi-dry air pollution control, without flue gas condensation, with electricity recovery only
A4: location | B4: RER
A5: production amount | B5: 1
A6: source | B6: Valentina Bisinella, Tore Hulgaard, Christian Riber, Anders Damgaard, Thomas H. Christensen, Environmental assessment of carbon capture and storage (CCS) as a post-treatment technology in waste incineration, Waste Management, Volume 128, 2021, Pages 99-113, ISSN 0956-053X, https://doi.org/10.1016/j.wasman.2021.04.046.
A7: reference product
A8: type | B8: process
A9: unit
A10: comment | B10: The incineration plant is a multi-output activity: 1) waste treatment, 2) heat production, 3) electricity production. Data on MSW composition as received at an incinerator in Copenhagen, Denmark. The estimated lower heating value is 9.9 GJ/tonne wet waste, and total carbon content is 264 kg C/tonne wet waste, 39% of which is fossil and 61% biogenic. Lower heating value (GJ/tonne ww): 9.9. Water content (kg/tonne ww): 432. Fossil carbon content (kg C/tonne ww): 102. Biogenic carbon content (kg C/tonne ww): 162. Air Pollution Contral (APC): Semi-dry. Flue gas condensation: No. Power production: Yes. Heat production: No. Carbon capture: No. Electricity production per ton MSWI incinerated: 739 kWh.
A11: Exchanges
A12: name | B12: amount | C12: location | D12: unit | E12: categories | F12: type | G12: reference product | H12: comment | I12: uncertainty type | J12: loc | K12: u1 | L12: u2 | M12: u3 | N12: u4 | O12: u5 | P12: u6 | Q12: ub | R12: scale | S12: negative
A13: municipal waste incineration, at incineration plant, with semi-dry air pollution control, without flue gas condensation, with electricity recovery only | B13: 1000 | C13: RER | D13: kilogram | F13: production | G13: municipal solid waste | I13: 0
A14: municipal waste incineration, at incineration plant, with semi-dry air pollution control, without flue gas condensation, with electricity recovery only | B14: 739 | C14: RER | D14: kilowatt hour | F14: production | G14: electricity, medium voltage | I14: 0
A15: municipal waste incineration, at incineration plant, with semi-dry air pollution control, without flue gas condensation, with electricity recovery only | B15: 0 | C15: RER | D15: megajoule | F15: production | G15: heat, district or industrial, other than natural gas | I15: 0
A16: market for diesel, low-sulfur | B16: =0.1*0.85 -> 0.085 | C16: Europe without Switzerland | D16: kilogram | F16: technosphere | G16: diesel, low-sulfur | H16: Diesel density: 0.85 kg/l | I16: 2 | J16: =LN(B16) -> -2.465104 | K16: 1 | L16: 1 | M16: 1 | N16: 1.02 | O16: 1.2 | P16: 1 | Q16: 1.05 | R16: =LN(SQRT(EXP( SQRT( +POWER(LN(K16),2) +POWER(LN(L16),2) +POWER(LN(M16),2) +POWER(LN(N16),2) +POWER(LN(O16),2) +POWER(LN(P16),2) +POWER(LN(Q16),2) ) ))) -> 0.094886477
A17: market for activated carbon, granular | B17: 0.4 | C17: GLO | D17: kilogram | F17: technosphere | G17: activated carbon, granular | I17: 2 | J17: =LN(B17) -> -0.91629073 | K17: 1 | L17: 1 | M17: 1 | N17: 1.02 | O17: 1.2 | P17: 1 | Q17: 1.05 | R17: =LN(SQRT(EXP( SQRT( +POWER(LN(K17),2) +POWER(LN(L17),2) +POWER(LN(M17),2) +POWER(LN(N17),2) +POWER(LN(O17),2) +POWER(LN(P17),2) +POWER(LN(Q17),2) ) ))) -> 0.094886477
A18: market for ammonia, anhydrous, liquid | B18: =4*24.5% -> 0.98 | C18: RER | D18: kilogram | F18: technosphere | G18: ammonia, anhydrous, liquid | H18: 100% liquid ammonia. In original publication, it is dilluated to 23.5% in water. We discount the original value by 75%. | I18: 2 | J18: =LN(B18) -> -0.020202707 | K18: 1 | L18: 1 | M18: 1 | N18: 1.02 | O18: 1.2 | P18: 1 | Q18: 1.05 | R18: =LN(SQRT(EXP( SQRT( +POWER(LN(K18),2) +POWER(LN(L18),2) +POWER(LN(M18),2) +POWER(LN(N18),2) +POWER(LN(O18),2) +POWER(LN(P18),2) +POWER(LN(Q18),2) ) ))) -> 0.094886477
A19: market for tap water | B19: =4-B18 -> 3.02 | C19: Europe without Switzerland | D19: kilogram | F19: technosphere | H19: Used to dilute the ammonia. | I19: 2 | J19: =LN(B19) -> 1.1052568 | K19: 1 | L19: 1 | M19: 1 | N19: 1.02 | O19: 1.2 | P19: 1 | Q19: 1.05 | R19: =LN(SQRT(EXP( SQRT( +POWER(LN(K19),2) +POWER(LN(L19),2) +POWER(LN(M19),2) +POWER(LN(N19),2) +POWER(LN(O19),2) +POWER(LN(P19),2) +POWER(LN(Q19),2) ) ))) -> 0.094886477
A20: market for calcium carbonate, precipitated | B20: 0 | C20: RER | D20: kilogram | F20: technosphere | G20: calcium carbonate, precipitated | I20: 0
A21: market for iron(III) chloride, without water, in 40% solution state | B21: 0 | C21: RER | D21: kilogram | F21: technosphere | G21: iron(III) chloride, without water, in 40% solution state | I21: 0
A22: market for lime, hydrated, packed | B22: 11 | C22: RER | D22: kilogram | F22: technosphere | G22: lime, hydrated, packed | I22: 2 | J22: =LN(B22) -> 2.3978953 | K22: 1 | L22: 1 | M22: 1 | N22: 1.02 | O22: 1.2 | P22: 1 | Q22: 1.05 | R22: =LN(SQRT(EXP( SQRT( +POWER(LN(K22),2) +POWER(LN(L22),2) +POWER(LN(M22),2) +POWER(LN(N22),2) +POWER(LN(O22),2) +POWER(LN(P22),2) +POWER(LN(Q22),2) ) ))) -> 0.094886477
A23: market for sodium hydroxide, without water, in 50% solution state | B23: 0 | C23: RER | D23: kilogram | F23: technosphere | G23: sodium hydroxide, without water, in 50% solution state | H23: 50% liquid ammonia. In original publication, it is dilluated to 27% in water. We discount the original value by 50%. | I23: 0
A24: market for monoethanolamine | B24: 0 | C24: GLO | D24: kilogram | F24: technosphere | G24: monoethanolamine | I24: 0
A25: municipal waste incineration facility construction | B25: 2.5e-07 | C25: CH | D25: unit | F25: technosphere | G25: municipal waste incineration facility | H25: Lifetime: 4'000'000 tons MSWI treated. | I25: 2 | J25: =LN(B25) -> -15.201805 | K25: 1 | L25: 1 | M25: 1 | N25: 1.02 | O25: 1.2 | P25: 1 | Q25: 3 | R25: =LN(SQRT(EXP( SQRT( +POWER(LN(K25),2) +POWER(LN(L25),2) +POWER(LN(M25),2) +POWER(LN(N25),2) +POWER(LN(O25),2) +POWER(LN(P25),2) +POWER(LN(Q25),2) ) ))) -> 0.55690714
A26: Water, cooling, unspecified natural origin | B26: 0.15 | D26: cubic meter | F26: biosphere | I26: 2 | J26: =LN(B26) -> -1.89712 | K26: 1 | L26: 1 | M26: 1 | N26: 1.02 | O26: 1.2 | P26: 1 | Q26: 1.05 | R26: =LN(SQRT(EXP( SQRT( +POWER(LN(K26),2) +POWER(LN(L26),2) +POWER(LN(M26),2) +POWER(LN(N26),2) +POWER(LN(O26),2) +POWER(LN(P26),2) +POWER(LN(Q26),2) ) ))) -> 0.094886477
A27: Sulfur dioxide | B27: 0.113 | D27: kilogram | E27: air::urban air close to ground | F27: biosphere | I27: 2 | J27: =LN(B27) -> -2.1803675 | K27: 1 | L27: 1 | M27: 1 | N27: 1.02 | O27: 1.2 | P27: 1 | Q27: 1.05 | R27: =LN(SQRT(EXP( SQRT( +POWER(LN(K27),2) +POWER(LN(L27),2) +POWER(LN(M27),2) +POWER(LN(N27),2) +POWER(LN(O27),2) +POWER(LN(P27),2) +POWER(LN(Q27),2) ) ))) -> 0.094886477
A28: Hydrochloric acid | B28: 0.028 | D28: kilogram | E28: air::urban air close to ground | F28: biosphere | I28: 2 | J28: =LN(B28) -> -3.5755508 | K28: 1 | L28: 1 | M28: 1 | N28: 1.02 | O28: 1.2 | P28: 1 | Q28: 1.5 | R28: =LN(SQRT(EXP( SQRT( +POWER(LN(K28),2) +POWER(LN(L28),2) +POWER(LN(M28),2) +POWER(LN(N28),2) +POWER(LN(O28),2) +POWER(LN(P28),2) +POWER(LN(Q28),2) ) ))) -> 0.22250576
A29: Nitrogen oxides | B29: 0.677 | D29: kilogram | E29: air::urban air close to ground | F29: biosphere | I29: 2 | J29: =LN(B29) -> -0.39008401 | K29: 1 | L29: 1 | M29: 1 | N29: 1.02 | O29: 1.2 | P29: 1 | Q29: 1.5 | R29: =LN(SQRT(EXP( SQRT( +POWER(LN(K29),2) +POWER(LN(L29),2) +POWER(LN(M29),2) +POWER(LN(N29),2) +POWER(LN(O29),2) +POWER(LN(P29),2) +POWER(LN(Q29),2) ) ))) -> 0.22250576
A30: Ammonia | B30: 0.045 | D30: kilogram | E30: air::urban air close to ground | F30: biosphere | I30: 2 | J30: =LN(B30) -> -3.1010928 | K30: 1 | L30: 1 | M30: 1 | N30: 1.02 | O30: 1.2 | P30: 1 | Q30: 1.5 | R30: =LN(SQRT(EXP( SQRT( +POWER(LN(K30),2) +POWER(LN(L30),2) +POWER(LN(M30),2) +POWER(LN(N30),2) +POWER(LN(O30),2) +POWER(LN(P30),2) +POWER(LN(Q30),2) ) ))) -> 0.22250576
A31: Particulate Matter, < 2.5 um | B31: 0.006 | D31: kilogram | E31: air::urban air close to ground | F31: biosphere | I31: 2 | J31: =LN(B31) -> -5.1159958 | K31: 1 | L31: 1 | M31: 1 | N31: 1.02 | O31: 1.2 | P31: 1 | Q31: 3 | R31: =LN(SQRT(EXP( SQRT( +POWER(LN(K31),2) +POWER(LN(L31),2) +POWER(LN(M31),2) +POWER(LN(N31),2) +POWER(LN(O31),2) +POWER(LN(P31),2) +POWER(LN(Q31),2) ) ))) -> 0.55690714
A32: Mercury II | B32: 2.3e-05 | D32: kilogram | E32: air::urban air close to ground | F32: biosphere | I32: 2 | J32: =LN(B32) -> -10.680016 | K32: 1 | L32: 1 | M32: 1 | N32: 1.02 | O32: 1.2 | P32: 1 | Q32: 5 | R32: =LN(SQRT(EXP( SQRT( +POWER(LN(K32),2) +POWER(LN(L32),2) +POWER(LN(M32),2) +POWER(LN(N32),2) +POWER(LN(O32),2) +POWER(LN(P32),2) +POWER(LN(Q32),2) ) ))) -> 0.80992649
A33: Lead II | B33: 5.6e-05 | D33: kilogram | E33: air::urban air close to ground | F33: biosphere | I33: 2 | J33: =LN(B33) -> -9.7901589 | K33: 1 | L33: 1 | M33: 1 | N33: 1.02 | O33: 1.2 | P33: 1 | Q33: 5 | R33: =LN(SQRT(EXP( SQRT( +POWER(LN(K33),2) +POWER(LN(L33),2) +POWER(LN(M33),2) +POWER(LN(N33),2) +POWER(LN(O33),2) +POWER(LN(P33),2) +POWER(LN(Q33),2) ) ))) -> 0.80992649
A34: Cadmium II | B34: 2.8e-05 | D34: kilogram | E34: air::urban air close to ground | F34: biosphere | I34: 2 | J34: =LN(B34) -> -10.483306 | K34: 1 | L34: 1 | M34: 1 | N34: 1.02 | O34: 1.2 | P34: 1 | Q34: 5 | R34: =LN(SQRT(EXP( SQRT( +POWER(LN(K34),2) +POWER(LN(L34),2) +POWER(LN(M34),2) +POWER(LN(N34),2) +POWER(LN(O34),2) +POWER(LN(P34),2) +POWER(LN(Q34),2) ) ))) -> 0.80992649
A35: Arsenic ion | B35: 6e-06 | D35: kilogram | E35: air::urban air close to ground | F35: biosphere | I35: 2 | J35: =LN(B35) -> -12.023751 | K35: 1 | L35: 1 | M35: 1 | N35: 1.02 | O35: 1.2 | P35: 1 | Q35: 5 | R35: =LN(SQRT(EXP( SQRT( +POWER(LN(K35),2) +POWER(LN(L35),2) +POWER(LN(M35),2) +POWER(LN(N35),2) +POWER(LN(O35),2) +POWER(LN(P35),2) +POWER(LN(Q35),2) ) ))) -> 0.80992649
A36: Dioxins, measured as 2,3,7,8-tetrachlorodibenzo-p-dioxin | B36: =0.11*0.000000001 -> 1.1e-10 | D36: kilogram | E36: air::urban air close to ground | F36: biosphere | I36: 2 | J36: =LN(B36) -> -22.930541 | K36: 1 | L36: 1 | M36: 1 | N36: 1.02 | O36: 1.2 | P36: 1 | Q36: 5 | R36: =LN(SQRT(EXP( SQRT( +POWER(LN(K36),2) +POWER(LN(L36),2) +POWER(LN(M36),2) +POWER(LN(N36),2) +POWER(LN(O36),2) +POWER(LN(P36),2) +POWER(LN(Q36),2) ) ))) -> 0.80992649
A37: Carbon dioxide, fossil | B37: 374 | D37: kilogram | E37: air::urban air close to ground | F37: biosphere | I37: 2 | J37: =LN(B37) -> 5.9242558 | K37: 1 | L37: 1 | M37: 1 | N37: 1.02 | O37: 1.2 | P37: 1 | Q37: 1.05 | R37: =LN(SQRT(EXP( SQRT( +POWER(LN(K37),2) +POWER(LN(L37),2) +POWER(LN(M37),2) +POWER(LN(N37),2) +POWER(LN(O37),2) +POWER(LN(P37),2) +POWER(LN(Q37),2) ) ))) -> 0.094886477
A38: Carbon dioxide, non-fossil | B38: 594 | D38: kilogram | E38: air::urban air close to ground | F38: biosphere | I38: 2 | J38: =LN(B38) -> 6.3868793 | K38: 1 | L38: 1 | M38: 1 | N38: 1.02 | O38: 1.2 | P38: 1 | Q38: 1.05 | R38: =LN(SQRT(EXP( SQRT( +POWER(LN(K38),2) +POWER(LN(L38),2) +POWER(LN(M38),2) +POWER(LN(N38),2) +POWER(LN(O38),2) +POWER(LN(P38),2) +POWER(LN(Q38),2) ) ))) -> 0.094886477
A40: Activity | B40: municipal waste incineration, at incineration plant, with semi-dry air pollution control, without flue gas condensation, with electricity and heat recovery
A41: location | B41: RER
A42: production amount | B42: 1
...

Sheet unallocated (consequential)
A1: Activity | B1: municipal waste incineration, at incineration plant, with semi-dry air pollution control, without flue gas condensation, with electricity recovery only
A2: location | B2: RER
A3: production amount | B3: 1
A4: source | B4: Valentina Bisinella, Tore Hulgaard, Christian Riber, Anders Damgaard, Thomas H. Christensen, Environmental assessment of carbon capture and storage (CCS) as a post-treatment technology in waste incineration, Waste Management, Volume 128, 2021, Pages 99-113, ISSN 0956-053X, https://doi.org/10.1016/j.wasman.2021.04.046.
A5: reference product | B5: municipal solid waste
A6: type | B6: process
A7: unit | B7: kilogram
A8: comment | B8: The incineration plant is a multi-output activity: 1) waste treatment, 2) heat production, 3) electricity production. Data on MSW composition as received at an incinerator in Copenhagen, Denmark. The estimated lower heating value is 9.9 GJ/tonne wet waste, and total carbon content is 264 kg C/tonne wet waste, 39% of which is fossil and 61% biogenic. Lower heating value (GJ/tonne ww): 9.9. Water content (kg/tonne ww): 432. Fossil carbon content (kg C/tonne ww): 102. Biogenic carbon content (kg C/tonne ww): 162. Air Pollution Contral (APC): Semi-dry. Flue gas condensation: No. Power production: Yes. Heat production: No. Carbon capture: No. Electricity production per ton MSWI incinerated: 739 kWh.
A9: Exchanges
A10: name | B10: amount | C10: location | D10: unit | E10: categories | F10: type | G10: reference product | H10: comment | I10: normalization | J10: uncertainty type | K10: loc | L10: u1 | M10: u2 | N10: u3 | O10: u4 | P10: u5 | Q10: u6 | R10: ub | S10: scale
A11: municipal waste incineration, at incineration plant, with semi-dry air pollution control, without flue gas condensation, with electricity recovery only | B11: =unallocated!B13/I11 -> 1 | C11: RER | D11: kilogram | F11: production | G11: municipal solid waste | I11: 1000 | J11: 0
A12: market group for electricity, medium voltage | B12: =unallocated!B14/I12 -> -0.739 | C12: RER | D12: kilowatt hour | F12: technosphere | G12: electricity, medium voltage | H12: Co-produced heat and electricity. | I12: -1000 | J12: 0
A13: market for diesel, low-sulfur | B13: =unallocated!B16/I13 -> 8.5e-05 | C13: Europe without Switzerland | D13: kilogram | F13: technosphere | G13: diesel, low-sulfur | H13: Diesel density: 0.85 kg/l | I13: 1000 | J13: 2 | K13: =LN(B13) -> -9.3728593 | L13: 1 | M13: 1 | N13: 1 | O13: 1.02 | P13: 1.2 | Q13: 1 | R13: 1.05 | S13: =LN(SQRT(EXP( SQRT( +POWER(LN(L13),2) +POWER(LN(M13),2) +POWER(LN(N13),2) +POWER(LN(O13),2) +POWER(LN(P13),2) +POWER(LN(Q13),2) +POWER(LN(R13),2) ) ))) -> 0.094886477
A14: market for activated carbon, granular | B14: =unallocated!B17/I14 -> 0.0004 | C14: GLO | D14: kilogram | F14: technosphere | G14: activated carbon, granular | I14: 1000 | J14: 2 | K14: =LN(B14) -> -7.824046 | L14: 1 | M14: 1 | N14: 1 | O14: 1.02 | P14: 1.2 | Q14: 1 | R14: 1.05 | S14: =LN(SQRT(EXP( SQRT( +POWER(LN(L14),2) +POWER(LN(M14),2) +POWER(LN(N14),2) +POWER(LN(O14),2) +POWER(LN(P14),2) +POWER(LN(Q14),2) +POWER(LN(R14),2) ) ))) -> 0.094886477
A15: market for ammonia, anhydrous, liquid | B15: =unallocated!B18/I15 -> 0.00098 | C15: RER | D15: kilogram | F15: technosphere | G15: ammonia, anhydrous, liquid | H15: 100% liquid ammonia. In original publication, it is dilluated to 23.5% in water. We discount the original value by 75%. | I15: 1000 | J15: 2 | K15: =LN(B15) -> -6.927958 | L15: 1 | M15: 1 | N15: 1 | O15: 1.02 | P15: 1.2 | Q15: 1 | R15: 1.05 | S15: =LN(SQRT(EXP( SQRT( +POWER(LN(L15),2) +POWER(LN(M15),2) +POWER(LN(N15),2) +POWER(LN(O15),2) +POWER(LN(P15),2) +POWER(LN(Q15),2) +POWER(LN(R15),2) ) ))) -> 0.094886477
A16: market for tap water | B16: =unallocated!B19/I16 -> 0.00302 | C16: Europe without Switzerland | D16: kilogram | F16: technosphere | G16: tap water | H16: Used to dilute the ammonia. | I16: 1000 | J16: 2 | K16: =LN(B16) -> -5.8024984 | L16: 1 | M16: 1 | N16: 1 | O16: 1.02 | P16: 1.2 | Q16: 1 | R16: 1.05 | S16: =LN(SQRT(EXP( SQRT( +POWER(LN(L16),2) +POWER(LN(M16),2) +POWER(LN(N16),2) +POWER(LN(O16),2) +POWER(LN(P16),2) +POWER(LN(Q16),2) +POWER(LN(R16),2) ) ))) -> 0.094886477
A17: market for calcium carbonate, precipitated | B17: =unallocated!B20/I17 -> 0 | C17: RER | D17: kilogram | F17: technosphere | G17: calcium carbonate, precipitated | I17: 1000 | J17: 0
A18: market for iron(III) chloride, without water, in 40% solution state | B18: =unallocated!B21/I18 -> 0 | C18: GLO | D18: kilogram | F18: technosphere | G18: iron(III) chloride, without water, in 40% solution state | I18: 1000 | J18: 0
A19: market for lime, hydrated, packed | B19: =unallocated!B22/I19 -> 0.011 | C19: RER | D19: kilogram | F19: technosphere | G19: lime, hydrated, packed | I19: 1000 | J19: 2 | K19: =LN(B19) -> -4.50986 | L19: 1 | M19: 1 | N19: 1 | O19: 1.02 | P19: 1.2 | Q19: 1 | R19: 1.05 | S19: =LN(SQRT(EXP( SQRT( +POWER(LN(L19),2) +POWER(LN(M19),2) +POWER(LN(N19),2) +POWER(LN(O19),2) +POWER(LN(P19),2) +POWER(LN(Q19),2) +POWER(LN(R19),2) ) ))) -> 0.094886477
A20: market for sodium hydroxide, without water, in 50% solution state | B20: =unallocated!B23/I20 -> 0 | C20: RER | D20: kilogram | F20: technosphere | G20: sodium hydroxide, without water, in 50% solution state | H20: 50% liquid ammonia. In original publication, it is dilluated to 27% in water. We discount the original value by 50%. | I20: 1000 | J20: 0
A21: market for monoethanolamine | B21: =unallocated!B24/I21 -> 0 | C21: GLO | D21: kilogram | F21: technosphere | G21: monoethanolamine | I21: 1000 | J21: 0
A22: municipal waste incineration facility construction | B22: =unallocated!B25/I22 -> 2.5e-10 | C22: CH | D22: unit | F22: technosphere | G22: municipal waste incineration facility | H22: Lifetime: 4'000'000 tons MSWI treated. | I22: 1000 | J22: 2 | K22: =LN(B22) -> -22.10956 | L22: 1 | M22: 1 | N22: 1 | O22: 1.02 | P22: 1.2 | Q22: 1 | R22: 3 | S22: =LN(SQRT(EXP( SQRT( +POWER(LN(L22),2) +POWER(LN(M22),2) +POWER(LN(N22),2) +POWER(LN(O22),2) +POWER(LN(P22),2) +POWER(LN(Q22),2) +POWER(LN(R22),2) ) ))) -> 0.55690714
A23: Water, cooling, unspecified natural origin | B23: =unallocated!B26/I23 -> 0.00015 | D23: cubic meter | E23: natural resource::in water | F23: biosphere | I23: 1000 | J23: 2 | K23: =LN(B23) -> -8.8048753 | L23: 1 | M23: 1 | N23: 1 | O23: 1.02 | P23: 1.2 | Q23: 1 | R23: 1.05 | S23: =LN(SQRT(EXP( SQRT( +POWER(LN(L23),2) +POWER(LN(M23),2) +POWER(LN(N23),2) +POWER(LN(O23),2) +POWER(LN(P23),2) +POWER(LN(Q23),2) +POWER(LN(R23),2) ) ))) -> 0.094886477
A24: Sulfur dioxide | B24: =unallocated!B27/I24 -> 0.000113 | D24: kilogram | E24: air::urban air close to ground | F24: biosphere | I24: 1000 | J24: 2 | K24: =LN(B24) -> -9.0881227 | L24: 1 | M24: 1 | N24: 1 | O24: 1.02 | P24: 1.2 | Q24: 1 | R24: 1.05 | S24: =LN(SQRT(EXP( SQRT( +POWER(LN(L24),2) +POWER(LN(M24),2) +POWER(LN(N24),2) +POWER(LN(O24),2) +POWER(LN(P24),2) +POWER(LN(Q24),2) +POWER(LN(R24),2) ) ))) -> 0.094886477
A25: Hydrochloric acid | B25: =unallocated!B28/I25 -> 2.8e-05 | D25: kilogram | E25: air | F25: biosphere | I25: 1000 | J25: 2 | K25: =LN(B25) -> -10.483306 | L25: 1 | M25: 1 | N25: 1 | O25: 1.02 | P25: 1.2 | Q25: 1 | R25: 1.5 | S25: =LN(SQRT(EXP( SQRT( +POWER(LN(L25),2) +POWER(LN(M25),2) +POWER(LN(N25),2) +POWER(LN(O25),2) +POWER(LN(P25),2) +POWER(LN(Q25),2) +POWER(LN(R25),2) ) ))) -> 0.22250576
A26: Nitrogen oxides | B26: =unallocated!B29/I26 -> 0.000677 | D26: kilogram | E26: air::urban air close to ground | F26: biosphere | I26: 1000 | J26: 2 | K26: =LN(B26) -> -7.2978393 | L26: 1 | M26: 1 | N26: 1 | O26: 1.02 | P26: 1.2 | Q26: 1 | R26: 1.5 | S26: =LN(SQRT(EXP( SQRT( +POWER(LN(L26),2) +POWER(LN(M26),2) +POWER(LN(N26),2) +POWER(LN(O26),2) +POWER(LN(P26),2) +POWER(LN(Q26),2) +POWER(LN(R26),2) ) ))) -> 0.22250576
A27: Ammonia | B27: =unallocated!B30/I27 -> 4.5e-05 | D27: kilogram | E27: air::urban air close to ground | F27: biosphere | I27: 1000 | J27: 2 | K27: =LN(B27) -> -10.008848 | L27: 1 | M27: 1 | N27: 1 | O27: 1.02 | P27: 1.2 | Q27: 1 | R27: 1.5 | S27: =LN(SQRT(EXP( SQRT( +POWER(LN(L27),2) +POWER(LN(M27),2) +POWER(LN(N27),2) +POWER(LN(O27),2) +POWER(LN(P27),2) +POWER(LN(Q27),2) +POWER(LN(R27),2) ) ))) -> 0.22250576
A28: Particulate Matter, < 2.5 um | B28: =unallocated!B31/I28 -> 6e-06 | D28: kilogram | E28: air::urban air close to ground | F28: biosphere | I28: 1000 | J28: 2 | K28: =LN(B28) -> -12.023751 | L28: 1 | M28: 1 | N28: 1 | O28: 1.02 | P28: 1.2 | Q28: 1 | R28: 3 | S28: =LN(SQRT(EXP( SQRT( +POWER(LN(L28),2) +POWER(LN(M28),2) +POWER(LN(N28),2) +POWER(LN(O28),2) +POWER(LN(P28),2) +POWER(LN(Q28),2) +POWER(LN(R28),2) ) ))) -> 0.55690714
A29: Mercury II | B29: =unallocated!B32/I29 -> 2.3e-08 | D29: kilogram | E29: air::urban air close to ground | F29: biosphere | I29: 1000 | J29: 2 | K29: =LN(B29) -> -17.587772 | L29: 1 | M29: 1 | N29: 1 | O29: 1.02 | P29: 1.2 | Q29: 1 | R29: 5 | S29: =LN(SQRT(EXP( SQRT( +POWER(LN(L29),2) +POWER(LN(M29),2) +POWER(LN(N29),2) +POWER(LN(O29),2) +POWER(LN(P29),2) +POWER(LN(Q29),2) +POWER(LN(R29),2) ) ))) -> 0.80992649
A30: Lead II | B30: =unallocated!B33/I30 -> 5.6e-08 | D30: kilogram | E30: air::urban air close to ground | F30: biosphere | I30: 1000 | J30: 2 | K30: =LN(B30) -> -16.697914 | L30: 1 | M30: 1 | N30: 1 | O30: 1.02 | P30: 1.2 | Q30: 1 | R30: 5 | S30: =LN(SQRT(EXP( SQRT( +POWER(LN(L30),2) +POWER(LN(M30),2) +POWER(LN(N30),2) +POWER(LN(O30),2) +POWER(LN(P30),2) +POWER(LN(Q30),2) +POWER(LN(R30),2) ) ))) -> 0.80992649
A31: Cadmium II | B31: =unallocated!B34/I31 -> 2.8e-08 | D31: kilogram | E31: air::urban air close to ground | F31: biosphere | I31: 1000 | J31: 2 | K31: =LN(B31) -> -17.391061 | L31: 1 | M31: 1 | N31: 1 | O31: 1.02 | P31: 1.2 | Q31: 1 | R31: 5 | S31: =LN(SQRT(EXP( SQRT( +POWER(LN(L31),2) +POWER(LN(M31),2) +POWER(LN(N31),2) +POWER(LN(O31),2) +POWER(LN(P31),2) +POWER(LN(Q31),2) +POWER(LN(R31),2) ) ))) -> 0.80992649
A32: Arsenic ion | B32: =unallocated!B35/I32 -> 6e-09 | D32: kilogram | E32: air::urban air close to ground | F32: biosphere | I32: 1000 | J32: 2 | K32: =LN(B32) -> -18.931506 | L32: 1 | M32: 1 | N32: 1 | O32: 1.02 | P32: 1.2 | Q32: 1 | R32: 5 | S32: =LN(SQRT(EXP( SQRT( +POWER(LN(L32),2) +POWER(LN(M32),2) +POWER(LN(N32),2) +POWER(LN(O32),2) +POWER(LN(P32),2) +POWER(LN(Q32),2) +POWER(LN(R32),2) ) ))) -> 0.80992649
A33: Dioxins, measured as 2,3,7,8-tetrachlorodibenzo-p-dioxin | B33: =unallocated!B36/I33 -> 1.1e-13 | D33: kilogram | E33: air::urban air close to ground | F33: biosphere | I33: 1000 | J33: 2 | K33: =LN(B33) -> -29.838296 | L33: 1 | M33: 1 | N33: 1 | O33: 1.02 | P33: 1.2 | Q33: 1 | R33: 5 | S33: =LN(SQRT(EXP( SQRT( +POWER(LN(L33),2) +POWER(LN(M33),2) +POWER(LN(N33),2) +POWER(LN(O33),2) +POWER(LN(P33),2) +POWER(LN(Q33),2) +POWER(LN(R33),2) ) ))) -> 0.80992649
A34: Carbon dioxide, fossil | B34: =unallocated!B37/I34 -> 0.374 | D34: kilogram | E34: air::urban air close to ground | F34: biosphere | I34: 1000 | J34: 2 | K34: =LN(B34) -> -0.98349948 | L34: 1 | M34: 1 | N34: 1 | O34: 1.02 | P34: 1.2 | Q34: 1 | R34: 1.05 | S34: =LN(SQRT(EXP( SQRT( +POWER(LN(L34),2) +POWER(LN(M34),2) +POWER(LN(N34),2) +POWER(LN(O34),2) +POWER(LN(P34),2) +POWER(LN(Q34),2) +POWER(LN(R34),2) ) ))) -> 0.094886477
A35: Carbon dioxide, non-fossil | B35: =unallocated!B38/I35 -> 0.594 | D35: kilogram | E35: air::urban air close to ground | F35: biosphere | I35: 1000 | J35: 2 | K35: =LN(B35) -> -0.52087596 | L35: 1 | M35: 1 | N35: 1 | O35: 1.02 | P35: 1.2 | Q35: 1 | R35: 1.05 | S35: =LN(SQRT(EXP( SQRT( +POWER(LN(L35),2) +POWER(LN(M35),2) +POWER(LN(N35),2) +POWER(LN(O35),2) +POWER(LN(P35),2) +POWER(LN(Q35),2) +POWER(LN(R35),2) ) ))) -> 0.094886477
A37: Activity | B37: municipal waste incineration, at incineration plant, with semi-dry air pollution control, without flue gas condensation, with electricity and heat recovery
A38: location | B38: RER
A39: production amount | B39: 1
A40: source | B40: Valentina Bisinella, Tore Hulgaard, Christian Riber, Anders Damgaard, Thomas H. Christensen, Environmental assessment of carbon capture and storage (CCS) as a post-treatment technology in waste incineration, Waste Management, Volume 128, 2021, Pages 99-113, ISSN 0956-053X, https://doi.org/10.1016/j.wasman.2021.04.046.
A41: reference product | B41: municipal solid waste
...

Sheet allocated (energy)
A1: Database | B1: Waste CHP
A3: Activity | B3: municipal waste incineration, at incineration plant, with semi-dry air pollution control, without flue gas condensation, with electricity recovery only, energy allocation
A4: location | B4: RER
A5: production amount | B5: 1
A6: source | B6: Valentina Bisinella, Tore Hulgaard, Christian Riber, Anders Damgaard, Thomas H. Christensen, Environmental assessment of carbon capture and storage (CCS) as a post-treatment technology in waste incineration, Waste Management, Volume 128, 2021, Pages 99-113, ISSN 0956-053X, https://doi.org/10.1016/j.wasman.2021.04.046.
A7: reference product | B7: municipal solid waste
A8: type | B8: process
A9: unit | B9: kilogram
A10: comment | B10: The incineration plant is a multi-output activity: 1) waste treatment, 2) heat production, 3) electricity production. Data on MSW composition as received at an incinerator in Copenhagen, Denmark. The estimated lower heating value is 9.9 GJ/tonne wet waste, and total carbon content is 264 kg C/tonne wet waste, 39% of which is fossil and 61% biogenic. Lower heating value (GJ/tonne ww): 9.9. Water content (kg/tonne ww): 432. Fossil carbon content (kg C/tonne ww): 102. Biogenic carbon content (kg C/tonne ww): 162. Air Pollution Contral (APC): Semi-dry. Flue gas condensation: No. Power production: Yes. Heat production: No. Carbon capture: No. Electricity production per ton MSWI incinerated: 739 kWh.
A11: Exchanges
A12: name | B12: amount | C12: location | D12: unit | E12: categories | F12: type | G12: reference product | H12: comment | I12: normalization | J12: allocation | K12: uncertainty type | L12: loc | M12: u1 | N12: u2 | O12: u3 | P12: u4 | Q12: u5 | R12: u6 | S12: ub | T12: scale | U12: negative
A13: municipal waste incineration, at incineration plant, with semi-dry air pollution control, without flue gas condensation, with electricity recovery only, energy allocation | B13: 1 | C13: RER | D13: kilogram | F13: production | G13: municipal solid waste | I13: 1000 | J13: =INDEX('allocation keys'!$F$4:$H$28,MATCH('allocated (energy)'!$B$3,'allocation keys'!$B$4:$B$28,0),MATCH('allocated (energy)'!$B$7,'allocation keys'!$F$3:$H$3,0)) -> 0 | K13: 0
A14: municipal waste incineration, at incineration plant, with semi-dry air pollution control, without flue gas condensation, with electricity recovery only, energy allocation | B14: =unallocated!B14/'allocated (energy)'!I14*'allocated (energy)'!J14 -> 0 | C14: RER | D14: kilowatt hour | F14: technosphere | G14: electricity, medium voltage | I14: 1000 | J14: =J13 -> 0 | K14: 0
A15: market for diesel, low-sulfur | B15: =unallocated!B16/'allocated (energy)'!I15*'allocated (energy)'!J15 -> 0 | C15: Europe without Switzerland | D15: kilogram | F15: technosphere | G15: diesel, low-sulfur | H15: Diesel density: 0.85 kg/l | I15: 1000 | J15: =J13 -> 0 | K15: 0
A16: market for activated carbon, granular | B16: =unallocated!B17/'allocated (energy)'!I16*'allocated (energy)'!J16 -> 0 | C16: GLO | D16: kilogram | F16: technosphere | G16: activated carbon, granular | I16: 1000 | J16: =J13 -> 0 | K16: 0
A17: market for ammonia, anhydrous, liquid | B17: =unallocated!B18/'allocated (energy)'!I17*'allocated (energy)'!J17 -> 0 | C17: RER | D17: kilogram | F17: technosphere | G17: ammonia, anhydrous, liquid | H17: 100% liquid ammonia. In original publication, it is dilluated to 23.5% in water. We discount the original value by 75%. | I17: 1000 | J17: =J13 -> 0 | K17: 0
A18: market for tap water | B18: =unallocated!B19/'allocated (energy)'!I18*'allocated (energy)'!J18 -> 0 | C18: Europe without Switzerland | D18: kilogram | F18: technosphere | G18: tap water | H18: Used to dilute the ammonia. | I18: 1000 | J18: =J13 -> 0 | K18: 0
A19: market for calcium carbonate, precipitated | B19: =unallocated!B20/'allocated (energy)'!I19*'allocated (energy)'!J19 -> 0 | C19: RER | D19: kilogram | F19: technosphere | G19: calcium carbonate, precipitated | I19: 1000 | J19: =J13 -> 0 | K19: 0
A20: market for iron(III) chloride, without water, in 40% solution state | B20: =unallocated!B21/'allocated (energy)'!I20*'allocated (energy)'!J20 -> 0 | C20: GLO | D20: kilogram | F20: technosphere | G20: iron(III) chloride, without water, in 40% solution state | I20: 1000 | J20: =J13 -> 0 | K20: 0
A21: market for lime, hydrated, packed | B21: =unallocated!B22/'allocated (energy)'!I21*'allocated (energy)'!J21 -> 0 | C21: RER | D21: kilogram | F21: technosphere | G21: lime, hydrated, packed | I21: 1000 | J21: =J13 -> 0 | K21: 0
A22: market for sodium hydroxide, without water, in 50% solution state | B22: =unallocated!B23/'allocated (energy)'!I22*'allocated (energy)'!J22 -> 0 | C22: RER | D22: kilogram | F22: technosphere | G22: sodium hydroxide, without water, in 50% solution state | H22: 50% liquid ammonia. In original publication, it is dilluated to 27% in water. We discount the original value by 50%. | I22: 1000 | J22: =J13 -> 0 | K22: 0
A23: market for monoethanolamine | B23: =unallocated!B24/'allocated (energy)'!I23*'allocated (energy)'!J23 -> 0 | C23: GLO | D23: kilogram | F23: technosphere | G23: monoethanolamine | I23: 1000 | J23: =J13 -> 0 | K23: 0
A24: municipal waste incineration facility construction | B24: =unallocated!B25/'allocated (energy)'!I24*'allocated (energy)'!J24 -> 0 | C24: CH | D24: unit | F24: technosphere | G24: municipal waste incineration facility | H24: Lifetime: 4'000'000 tons MSWI treated. | I24: 1000 | J24: =J13 -> 0 | K24: 0
A25: Water, cooling, unspecified natural origin | B25: =unallocated!B26/'allocated (energy)'!I25*'allocated (energy)'!J25 -> 0 | D25: cubic meter | E25: natural resource::in water | F25: biosphere | I25: 1000 | J25: =J13 -> 0 | K25: 0
A26: Sulfur dioxide | B26: =unallocated!B27/'allocated (energy)'!I26*'allocated (energy)'!J26 -> 0 | D26: kilogram | E26: air::urban air close to ground | F26: biosphere | I26: 1000 | J26: =J13 -> 0 | K26: 0
A27: Hydrochloric acid | B27: =unallocated!B28/'allocated (energy)'!I27*'allocated (energy)'!J27 -> 0 | D27: kilogram | E27: air | F27: biosphere | I27: 1000 | J27: =J13 -> 0 | K27: 0
A28: Nitrogen oxides | B28: =unallocated!B29/'allocated (energy)'!I28*'allocated (energy)'!J28 -> 0 | D28: kilogram | E28: air::urban air close to ground | F28: biosphere | I28: 1000 | J28: =J13 -> 0 | K28: 0
A29: Ammonia | B29: =unallocated!B30/'allocated (energy)'!I29*'allocated (energy)'!J29 -> 0 | D29: kilogram | E29: air::urban air close to ground | F29: biosphere | I29: 1000 | J29: =J13 -> 0 | K29: 0
A30: Particulate Matter, < 2.5 um | B30: =unallocated!B31/'allocated (energy)'!I30*'allocated (energy)'!J30 -> 0 | D30: kilogram | E30: air::urban air close to ground | F30: biosphere | I30: 1000 | J30: =J13 -> 0 | K30: 0
A31: Mercury II | B31: =unallocated!B32/'allocated (energy)'!I31*'allocated (energy)'!J31 -> 0 | D31: kilogram | E31: air::urban air close to ground | F31: biosphere | I31: 1000 | J31: =J13 -> 0 | K31: 0
A32: Lead II | B32: =unallocated!B33/'allocated (energy)'!I32*'allocated (energy)'!J32 -> 0 | D32: kilogram | E32: air::urban air close to ground | F32: biosphere | I32: 1000 | J32: =J13 -> 0 | K32: 0
A33: Cadmium II | B33: =unallocated!B34/'allocated (energy)'!I33*'allocated (energy)'!J33 -> 0 | D33: kilogram | E33: air::urban air close to ground | F33: biosphere | I33: 1000 | J33: =J13 -> 0 | K33: 0
A34: Arsenic ion | B34: =unallocated!B35/'allocated (energy)'!I34*'allocated (energy)'!J34 -> 0 | D34: kilogram | E34: air::urban air close to ground | F34: biosphere | I34: 1000 | J34: =J13 -> 0 | K34: 0
A35: Dioxins, measured as 2,3,7,8-tetrachlorodibenzo-p-dioxin | B35: =unallocated!B36/'allocated (energy)'!I35*'allocated (energy)'!J35 -> 0 | D35: kilogram | E35: air::urban air close to ground | F35: biosphere | I35: 1000 | J35: =J13 -> 0 | K35: 0
A36: Carbon dioxide, fossil | B36: =unallocated!B37/'allocated (energy)'!I36*'allocated (energy)'!J36 -> 0 | D36: kilogram | E36: air::urban air close to ground | F36: biosphere | I36: 1000 | J36: =J13 -> 0 | K36: 0
A37: Carbon dioxide, non-fossil | B37: =unallocated!B38/'allocated (energy)'!I37*'allocated (energy)'!J37 -> 0 | D37: kilogram | E37: air::urban air close to ground | F37: biosphere | I37: 1000 | J37: =J13 -> 0 | K37: 0
A39: Activity | B39: municipal waste incineration, at incineration plant, with semi-dry air pollution control, without flue gas condensation, with electricity recovery only, energy allocation
A40: location | B40: RER
A41: production amount | B41: 1
A42: source | B42: Valentina Bisinella, Tore Hulgaard, Christian Riber, Anders Damgaard, Thomas H. Christensen, Environmental assessment of carbon capture and storage (CCS) as a post-treatment technology in waste incineration, Waste Management, Volume 128, 2021, Pages 99-113, ISSN 0956-053X, https://doi.org/10.1016/j.wasman.2021.04.046.
...

Sheet allocated (exergy)
A1: Activity | B1: municipal waste incineration, at incineration plant, with semi-dry air pollution control, without flue gas condensation, with electricity recovery only, exergy allocation
A2: location | B2: RER
A3: production amount | B3: 1
A4: source | B4: Valentina Bisinella, Tore Hulgaard, Christian Riber, Anders Damgaard, Thomas H. Christensen, Environmental assessment of carbon capture and storage (CCS) as a post-treatment technology in waste incineration, Waste Management, Volume 128, 2021, Pages 99-113, ISSN 0956-053X, https://doi.org/10.1016/j.wasman.2021.04.046.
A5: reference product | B5: municipal solid waste
A6: type | B6: process
A7: unit | B7: kilogram
A8: comment | B8: The incineration plant is a multi-output activity: 1) waste treatment, 2) heat production, 3) electricity production. Data on MSW composition as received at an incinerator in Copenhagen, Denmark. The estimated lower heating value is 9.9 GJ/tonne wet waste, and total carbon content is 264 kg C/tonne wet waste, 39% of which is fossil and 61% biogenic. Lower heating value (GJ/tonne ww): 9.9. Water content (kg/tonne ww): 432. Fossil carbon content (kg C/tonne ww): 102. Biogenic carbon content (kg C/tonne ww): 162. Air Pollution Contral (APC): Semi-dry. Flue gas condensation: No. Power production: Yes. Heat production: No. Carbon capture: No. Electricity production per ton MSWI incinerated: 739 kWh.
A9: Exchanges
A10: name | B10: amount | C10: location | D10: unit | E10: categories | F10: type | G10: reference product | H10: comment | I10: normalization | J10: allocation | K10: uncertainty type | L10: loc | M10: u1 | N10: u2 | O10: u3 | P10: u4 | Q10: u5 | R10: u6 | S10: ub | T10: scale | U10: negative
A11: municipal waste incineration, at incineration plant, with semi-dry air pollution control, without flue gas condensation, with electricity recovery only, exergy allocation | B11: 1 | C11: RER | D11: kilogram | F11: production | G11: municipal solid waste | I11: 1000 | J11: =INDEX('allocation keys'!$I$4:$K$29,MATCH('allocated (exergy)'!$B$1,'allocation keys'!$B$4:$B$28,0),MATCH('allocated (exergy)'!$B$5,'allocation keys'!$I$3:$K$3,0)) -> 0 | K11: 0
A12: municipal waste incineration, at incineration plant, with semi-dry air pollution control, without flue gas condensation, with electricity recovery only, exergy allocation | B12: =unallocated!B14/'allocated (exergy)'!I12*'allocated (exergy)'!J12 -> 0 | C12: RER | D12: kilowatt hour | F12: technosphere | G12: electricity, medium voltage | I12: 1000 | J12: =J11 -> 0 | K12: 0
A13: market for diesel, low-sulfur | B13: =unallocated!B16/'allocated (exergy)'!I13*'allocated (exergy)'!J13 -> 0 | C13: Europe without Switzerland | D13: kilogram | F13: technosphere | G13: diesel, low-sulfur | H13: Diesel density: 0.85 kg/l | I13: 1000 | J13: =J11 -> 0 | K13: 0
A14: market for activated carbon, granular | B14: =unallocated!B17/'allocated (exergy)'!I14*'allocated (exergy)'!J14 -> 0 | C14: GLO | D14: kilogram | F14: technosphere | G14: activated carbon, granular | I14: 1000 | J14: =J11 -> 0 | K14: 0
A15: market for ammonia, anhydrous, liquid | B15: =unallocated!B18/'allocated (exergy)'!I15*'allocated (exergy)'!J15 -> 0 | C15: RER | D15: kilogram | F15: technosphere | G15: ammonia, anhydrous, liquid | H15: 100% liquid ammonia. In original publication, it is dilluated to 23.5% in water. We discount the original value by 75%. | I15: 1000 | J15: =J11 -> 0 | K15: 0
A16: market for tap water | B16: =unallocated!B19/'allocated (exergy)'!I16*'allocated (exergy)'!J16 -> 0 | C16: Europe without Switzerland | D16: kilogram | F16: technosphere | G16: tap water | H16: Used to dilute the ammonia. | I16: 1000 | J16: =J11 -> 0 | K16: 0
A17: market for calcium carbonate, precipitated | B17: =unallocated!B20/'allocated (exergy)'!I17*'allocated (exergy)'!J17 -> 0 | C17: RER | D17: kilogram | F17: technosphere | G17: calcium carbonate, precipitated | I17: 1000 | J17: =J11 -> 0 | K17: 0
A18: market for iron(III) chloride, without water, in 40% solution state | B18: =unallocated!B21/'allocated (exergy)'!I18*'allocated (exergy)'!J18 -> 0 | C18: GLO | D18: kilogram | F18: technosphere | G18: iron(III) chloride, without water, in 40% solution state | I18: 1000 | J18: =J11 -> 0 | K18: 0
A19: market for lime, hydrated, packed | B19: =unallocated!B22/'allocated (exergy)'!I19*'allocated (exergy)'!J19 -> 0 | C19: RER | D19: kilogram | F19: technosphere | G19: lime, hydrated, packed | I19: 1000 | J19: =J11 -> 0 | K19: 0
A20: market for sodium hydroxide, without water, in 50% solution state | B20: =unallocated!B23/'allocated (exergy)'!I20*'allocated (exergy)'!J20 -> 0 | C20: RER | D20: kilogram | F20: technosphere | G20: sodium hydroxide, without water, in 50% solution state | H20: 50% liquid ammonia. In original publication, it is dilluated to 27% in water. We discount the original value by 50%. | I20: 1000 | J20: =J11 -> 0 | K20: 0
A21: market for monoethanolamine | B21: =unallocated!B24/'allocated (exergy)'!I21*'allocated (exergy)'!J21 -> 0 | C21: GLO | D21: kilogram | F21: technosphere | G21: monoethanolamine | I21: 1000 | J21: =J11 -> 0 | K21: 0
A22: municipal waste incineration facility construction | B22: =unallocated!B25/'allocated (exergy)'!I22*'allocated (exergy)'!J22 -> 0 | C22: CH | D22: unit | F22: technosphere | G22: municipal waste incineration facility | H22: Lifetime: 4'000'000 tons MSWI treated. | I22: 1000 | J22: =J11 -> 0 | K22: 0
A23: Water, cooling, unspecified natural origin | B23: =unallocated!B26/'allocated (exergy)'!I23*'allocated (exergy)'!J23 -> 0 | D23: cubic meter | E23: natural resource::in water | F23: biosphere | I23: 1000 | J23: =J11 -> 0 | K23: 0
A24: Sulfur dioxide | B24: =unallocated!B27/'allocated (exergy)'!I24*'allocated (exergy)'!J24 -> 0 | D24: kilogram | E24: air::urban air close to ground | F24: biosphere | I24: 1000 | J24: =J11 -> 0 | K24: 0
A25: Hydrochloric acid | B25: =unallocated!B28/'allocated (exergy)'!I25*'allocated (exergy)'!J25 -> 0 | D25: kilogram | E25: air | F25: biosphere | I25: 1000 | J25: =J11 -> 0 | K25: 0
A26: Nitrogen oxides | B26: =unallocated!B29/'allocated (exergy)'!I26*'allocated (exergy)'!J26 -> 0 | D26: kilogram | E26: air::urban air close to ground | F26: biosphere | I26: 1000 | J26: =J11 -> 0 | K26: 0
A27: Ammonia | B27: =unallocated!B30/'allocated (exergy)'!I27*'allocated (exergy)'!J27 -> 0 | D27: kilogram | E27: air::urban air close to ground | F27: biosphere | I27: 1000 | J27: =J11 -> 0 | K27: 0
A28: Particulate Matter, < 2.5 um | B28: =unallocated!B31/'allocated (exergy)'!I28*'allocated (exergy)'!J28 -> 0 | D28: kilogram | E28: air::urban air close to ground | F28: biosphere | I28: 1000 | J28: =J11 -> 0 | K28: 0
A29: Mercury II | B29: =unallocated!B32/'allocated (exergy)'!I29*'allocated (exergy)'!J29 -> 0 | D29: kilogram | E29: air::urban air close to ground | F29: biosphere | I29: 1000 | J29: =J11 -> 0 | K29: 0
A30: Lead II | B30: =unallocated!B33/'allocated (exergy)'!I30*'allocated (exergy)'!J30 -> 0 | D30: kilogram | E30: air::urban air close to ground | F30: biosphere | I30: 1000 | J30: =J11 -> 0 | K30: 0
A31: Cadmium II | B31: =unallocated!B34/'allocated (exergy)'!I31*'allocated (exergy)'!J31 -> 0 | D31: kilogram | E31: air::urban air close to ground | F31: biosphere | I31: 1000 | J31: =J11 -> 0 | K31: 0
A32: Arsenic ion | B32: =unallocated!B35/'allocated (exergy)'!I32*'allocated (exergy)'!J32 -> 0 | D32: kilogram | E32: air::urban air close to ground | F32: biosphere | I32: 1000 | J32: =J11 -> 0 | K32: 0
A33: Dioxins, measured as 2,3,7,8-tetrachlorodibenzo-p-dioxin | B33: =unallocated!B36/'allocated (exergy)'!I33*'allocated (exergy)'!J33 -> 0 | D33: kilogram | E33: air::urban air close to ground | F33: biosphere | I33: 1000 | J33: =J11 -> 0 | K33: 0
A34: Carbon dioxide, fossil | B34: =unallocated!B37/'allocated (exergy)'!I34*'allocated (exergy)'!J34 -> 0 | D34: kilogram | E34: air::urban air close to ground | F34: biosphere | I34: 1000 | J34: =J11 -> 0 | K34: 0
A35: Carbon dioxide, non-fossil | B35: =unallocated!B38/'allocated (exergy)'!I35*'allocated (exergy)'!J35 -> 0 | D35: kilogram | E35: air::urban air close to ground | F35: biosphere | I35: 1000 | J35: =J11 -> 0 | K35: 0
A37: Activity | B37: municipal waste incineration, at incineration plant, with semi-dry air pollution control, without flue gas condensation, with electricity recovery only, exergy allocation
A38: location | B38: RER
A39: production amount | B39: 1
A40: source | B40: Valentina Bisinella, Tore Hulgaard, Christian Riber, Anders Damgaard, Thomas H. Christensen, Environmental assessment of carbon capture and storage (CCS) as a post-treatment technology in waste incineration, Waste Management, Volume 128, 2021, Pages 99-113, ISSN 0956-053X, https://doi.org/10.1016/j.wasman.2021.04.046.
A41: reference product | B41: electricity, medium voltage
...

Sheet allocated (economic)
A1: Activity | B1: municipal waste incineration, at incineration plant, with semi-dry air pollution control, without flue gas condensation, with electricity recovery only, economic allocation
A2: location | B2: RER
A3: production amount | B3: 1
A4: source | B4: Valentina Bisinella, Tore Hulgaard, Christian Riber, Anders Damgaard, Thomas H. Christensen, Environmental assessment of carbon capture and storage (CCS) as a post-treatment technology in waste incineration, Waste Management, Volume 128, 2021, Pages 99-113, ISSN 0956-053X, https://doi.org/10.1016/j.wasman.2021.04.046.
A5: reference product | B5: municipal solid waste
A6: type | B6: process
A7: unit | B7: kilogram
A8: comment | B8: The incineration plant is a multi-output activity: 1) waste treatment, 2) heat production, 3) electricity production. Data on MSW composition as received at an incinerator in Copenhagen, Denmark. The estimated lower heating value is 9.9 GJ/tonne wet waste, and total carbon content is 264 kg C/tonne wet waste, 39% of which is fossil and 61% biogenic. Lower heating value (GJ/tonne ww): 9.9. Water content (kg/tonne ww): 432. Fossil carbon content (kg C/tonne ww): 102. Biogenic carbon content (kg C/tonne ww): 162. Air Pollution Contral (APC): Semi-dry. Flue gas condensation: No. Power production: Yes. Heat production: No. Carbon capture: No. Electricity production per ton MSWI incinerated: 739 kWh.
A9: Exchanges
A10: name | B10: amount | C10: location | D10: unit | E10: categories | F10: type | G10: reference product | H10: comment | I10: normalization | J10: allocation | K10: uncertainty type | L10: loc | M10: u1 | N10: u2 | O10: u3 | P10: u4 | Q10: u5 | R10: u6 | S10: ub | T10: scale | U10: negative
A11: municipal waste incineration, at incineration plant, with semi-dry air pollution control, without flue gas condensation, with electricity recovery only, economic allocation | B11: 1 | C11: RER | D11: kilogram | F11: production | G11: municipal solid waste | I11: 1000 | J11: =INDEX('allocation keys'!$L$4:$N$30,MATCH('allocated (economic)'!$B$1,'allocation keys'!$B$4:$B$28,0),MATCH('allocated (economic)'!$B$5,'allocation keys'!$L$3:$N$3,0)) -> 0.62657908 | K11: 0
A12: municipal waste incineration, at incineration plant, with semi-dry air pollution control, without flue gas condensation, with electricity recovery only, economic allocation | B12: 0 | C12: RER | D12: kilowatt hour | F12: technosphere | G12: electricity, medium voltage | I12: 1000 | J12: =J11 -> 0.62657908 | K12: 0
A13: market for diesel, low-sulfur | B13: =unallocated!B16/'allocated (economic)'!I13*'allocated (economic)'!J13 -> 5.3259222e-05 | C13: Europe without Switzerland | D13: kilogram | F13: technosphere | G13: diesel, low-sulfur | H13: Diesel density: 0.85 kg/l | I13: 1000 | J13: =J11 -> 0.62657908 | K13: 0
A14: market for activated carbon, granular | B14: =unallocated!B17/'allocated (economic)'!I14*'allocated (economic)'!J14 -> 0.00025063163 | C14: GLO | D14: kilogram | F14: technosphere | G14: activated carbon, granular | I14: 1000 | J14: =J11 -> 0.62657908 | K14: 0
A15: market for ammonia, anhydrous, liquid | B15: =unallocated!B18/'allocated (economic)'!I15*'allocated (economic)'!J15 -> 0.0006140475 | C15: RER | D15: kilogram | F15: technosphere | G15: ammonia, anhydrous, liquid | H15: 100% liquid ammonia. In original publication, it is dilluated to 23.5% in water. We discount the original value by 75%. | I15: 1000 | J15: =J11 -> 0.62657908 | K15: 0
A16: market for tap water | B16: =unallocated!B19/'allocated (economic)'!I16*'allocated (economic)'!J16 -> 0.0018922688 | C16: Europe without Switzerland | D16: kilogram | F16: technosphere | G16: tap water | H16: Used to dilute the ammonia. | I16: 1000 | J16: =J11 -> 0.62657908 | K16: 0
A17: market for calcium carbonate, precipitated | B17: =unallocated!B20/'allocated (economic)'!I17*'allocated (economic)'!J17 -> 0 | C17: RER | D17: kilogram | F17: technosphere | G17: calcium carbonate, precipitated | I17: 1000 | J17: =J11 -> 0.62657908 | K17: 0
A18: market for iron(III) chloride, without water, in 40% solution state | B18: =unallocated!B21/'allocated (economic)'!I18*'allocated (economic)'!J18 -> 0 | C18: GLO | D18: kilogram | F18: technosphere | G18: iron(III) chloride, without water, in 40% solution state | I18: 1000 | J18: =J11 -> 0.62657908 | K18: 0
A19: market for lime, hydrated, packed | B19: =unallocated!B22/'allocated (economic)'!I19*'allocated (economic)'!J19 -> 0.0068923699 | C19: RER | D19: kilogram | F19: technosphere | G19: lime, hydrated, packed | I19: 1000 | J19: =J11 -> 0.62657908 | K19: 0
A20: market for sodium hydroxide, without water, in 50% solution state | B20: =unallocated!B23/'allocated (economic)'!I20*'allocated (economic)'!J20 -> 0 | C20: RER | D20: kilogram | F20: technosphere | G20: sodium hydroxide, without water, in 50% solution state | H20: 50% liquid ammonia. In original publication, it is dilluated to 27% in water. We discount the original value by 50%. | I20: 1000 | J20: =J11 -> 0.62657908 | K20: 0
A21: market for monoethanolamine | B21: =unallocated!B24/'allocated (economic)'!I21*'allocated (economic)'!J21 -> 0 | C21: GLO | D21: kilogram | F21: technosphere | G21: monoethanolamine | I21: 1000 | J21: =J11 -> 0.62657908 | K21: 0
A22: municipal waste incineration facility construction | B22: =unallocated!B25/'allocated (economic)'!I22*'allocated (economic)'!J22 -> 1.5664477e-10 | C22: CH | D22: unit | F22: technosphere | G22: municipal waste incineration facility | H22: Lifetime: 4'000'000 tons MSWI treated. | I22: 1000 | J22: =J11 -> 0.62657908 | K22: 0
A23: Water, cooling, unspecified natural origin | B23: =unallocated!B26/'allocated (economic)'!I23*'allocated (economic)'!J23 -> 9.3986862e-05 | D23: cubic meter | E23: natural resource::in water | F23: biosphere | I23: 1000 | J23: =J11 -> 0.62657908 | K23: 0
A24: Sulfur dioxide | B24: =unallocated!B27/'allocated (economic)'!I24*'allocated (economic)'!J24 -> 7.0803436e-05 | D24: kilogram | E24: air::urban air close to ground | F24: biosphere | I24: 1000 | J24: =J11 -> 0.62657908 | K24: 0
A25: Hydrochloric acid | B25: =unallocated!B28/'allocated (economic)'!I25*'allocated (economic)'!J25 -> 1.7544214e-05 | D25: kilogram | E25: air | F25: biosphere | I25: 1000 | J25: =J11 -> 0.62657908 | K25: 0
A26: Nitrogen oxides | B26: =unallocated!B29/'allocated (economic)'!I26*'allocated (economic)'!J26 -> 0.00042419404 | D26: kilogram | E26: air::urban air close to ground | F26: biosphere | I26: 1000 | J26: =J11 -> 0.62657908 | K26: 0
A27: Ammonia | B27: =unallocated!B30/'allocated (economic)'!I27*'allocated (economic)'!J27 -> 2.8196059e-05 | D27: kilogram | E27: air::urban air close to ground | F27: biosphere | I27: 1000 | J27: =J11 -> 0.62657908 | K27: 0
A28: Particulate Matter, < 2.5 um | B28: =unallocated!B31/'allocated (economic)'!I28*'allocated (economic)'!J28 -> 3.7594745e-06 | D28: kilogram | E28: air::urban air close to ground | F28: biosphere | I28: 1000 | J28: =J11 -> 0.62657908 | K28: 0
A29: Mercury II | B29: =unallocated!B32/'allocated (economic)'!I29*'allocated (economic)'!J29 -> 1.4411319e-08 | D29: kilogram | E29: air::urban air close to ground | F29: biosphere | I29: 1000 | J29: =J11 -> 0.62657908 | K29: 0
A30: Lead II | B30: =unallocated!B33/'allocated (economic)'!I30*'allocated (economic)'!J30 -> 3.5088428e-08 | D30: kilogram | E30: air::urban air close to ground | F30: biosphere | I30: 1000 | J30: =J11 -> 0.62657908 | K30: 0
A31: Cadmium II | B31: =unallocated!B34/'allocated (economic)'!I31*'allocated (economic)'!J31 -> 1.7544214e-08 | D31: kilogram | E31: air::urban air close to ground | F31: biosphere | I31: 1000 | J31: =J11 -> 0.62657908 | K31: 0
A32: Arsenic ion | B32: =unallocated!B35/'allocated (economic)'!I32*'allocated (economic)'!J32 -> 3.7594745e-09 | D32: kilogram | E32: air::urban air close to ground | F32: biosphere | I32: 1000 | J32: =J11 -> 0.62657908 | K32: 0
A33: Dioxins, measured as 2,3,7,8-tetrachlorodibenzo-p-dioxin | B33: =unallocated!B36/'allocated (economic)'!I33*'allocated (economic)'!J33 -> 6.8923699e-14 | D33: kilogram | E33: air::urban air close to ground | F33: biosphere | I33: 1000 | J33: =J11 -> 0.62657908 | K33: 0
A34: Carbon dioxide, fossil | B34: =unallocated!B37/'allocated (economic)'!I34*'allocated (economic)'!J34 -> 0.23434058 | D34: kilogram | E34: air::urban air close to ground | F34: biosphere | I34: 1000 | J34: =J11 -> 0.62657908 | K34: 0
A35: Carbon dioxide, non-fossil | B35: =unallocated!B38/'allocated (economic)'!I35*'allocated (economic)'!J35 -> 0.37218797 | D35: kilogram | E35: air::urban air close to ground | F35: biosphere | I35: 1000 | J35: =J11 -> 0.62657908 | K35: 0
A37: Activity | B37: municipal waste incineration, at incineration plant, with semi-dry air pollution control, without flue gas condensation, with electricity recovery only, economic allocation
A38: location | B38: RER
A39: production amount | B39: 1
A40: source | B40: Valentina Bisinella, Tore Hulgaard, Christian Riber, Anders Damgaard, Thomas H. Christensen, Environmental assessment of carbon capture and storage (CCS) as a post-treatment technology in waste incineration, Waste Management, Volume 128, 2021, Pages 99-113, ISSN 0956-053X, https://doi.org/10.1016/j.wasman.2021.04.046.
A41: reference product | B41: electricity, medium voltage
...

Sheet allocation keys
A1: skip
F2: Energy allocation key | I2: Exergy allocation key | L2: Economic allocation key
B3: name | C3: waste input [kg] | D3: electricity output [kWh] | E3: heat output [MJ] | F3: municipal solid waste | G3: electricity, medium voltage | H3: heat, district or industrial, other than natural gas | I3: municipal solid waste | J3: electricity, medium voltage | K3: heat, district or industrial, other than natural gas | L3: municipal solid waste | M3: electricity, medium voltage | N3: heat, district or industrial, other than natural gas
B4: municipal waste incineration, at incineration plant, with semi-dry air pollution control, without flue gas condensation, with electricity recovery only, energy allocation | C4: 1000 | D4: 739 | F4: 0 | G4: =(D4*3.6)/((D4*3.6)+E4) -> 1 | H4: =(E4)/((D4*3.6)+E4) -> 0
B5: municipal waste incineration, at incineration plant, with semi-dry air pollution control, without flue gas condensation, with electricity recovery only, exergy allocation | I5: 0 | J5: =1-K5 -> 1 | K5: =(G39*F39)/((G39*F39)+(1*H39)) -> 0
B6: municipal waste incineration, at incineration plant, with semi-dry air pollution control, without flue gas condensation, with electricity recovery only, economic allocation | L6: =(C4/1000*$C$33)/((C4/1000*$C$33)+(D4/1000*$C$35)+(E4/1000*$C$34)) -> 0.62657908 | M6: =(D4/1000*$C$35)/((C4/1000*$C$33)+(D4/1000*$C$35)+(E4/1000*$C$34)) -> 0.37342092 | N6: =(E4/1000*$C$34)/((C4/1000*$C$33)+(D4/1000*$C$35)+(E4/1000*$C$34)) -> 0
B7: municipal waste incineration, at incineration plant, with semi-dry air pollution control, without flue gas condensation, with electricity and heat recovery, energy allocation | C7: 1000 | D7: 638 | E7: 6170 | F7: 0 | G7: =(D7*3.6)/((D7*3.6)+E7) -> 0.27127132 | H7: =(E7)/((D7*3.6)+E7) -> 0.72872868
B8: municipal waste incineration, at incineration plant, with semi-dry air pollution control, without flue gas condensation, with electricity and heat recovery, exergy allocation | I8: 0 | J8: =1-K8 -> 0.74618769 | K8: =(G40*F40)/((G40*F40)+(1*H40)) -> 0.25381231
B9: municipal waste incineration, at incineration plant, with semi-dry air pollution control, without flue gas condensation, with electricity and heat recovery, economic allocation | L9: =(C7/1000*$C$33)/((C7/1000*$C$33)+(D7/1000*$C$35)+(E7/1000*$C$34)) -> 0.48972757 | M9: =(D7/1000*$C$35)/((C7/1000*$C$33)+(D7/1000*$C$35)+(E7/1000*$C$34)) -> 0.25197273 | N9: =(E7/1000*$C$34)/((C7/1000*$C$33)+(D7/1000*$C$35)+(E7/1000*$C$34)) -> 0.2582997
B10: municipal waste incineration, at incineration plant, with semi-dry air pollution control, with flue gas condensation, with electricity and heat recovery, energy allocation | C10: 1000 | D10: 623 | E10: 7860 | F10: 0 | G10: =(D10*3.6)/((D10*3.6)+E10) -> 0.22199786 | H10: =(E10)/((D10*3.6)+E10) -> 0.77800214
B11: municipal waste incineration, at incineration plant, with semi-dry air pollution control, with flue gas condensation, with electricity and heat recovery, exergy allocation | I11: 0 | J11: =1-K11 -> 0.69264253 | K11: =(G41*F41)/((G41*F41)+(1*H41)) -> 0.30735747
B12: municipal waste incineration, at incineration plant, with semi-dry air pollution control, with flue gas condensation, with electricity and heat recovery, economic allocation | L12: =(C10/1000*$C$33)/((C10/1000*$C$33)+(D10/1000*$C$35)+(E10/1000*$C$34)) -> 0.45991336 | M12: =(D10/1000*$C$35)/((C10/1000*$C$33)+(D10/1000*$C$35)+(E10/1000*$C$34)) -> 0.23106937 | N12: =(E10/1000*$C$34)/((C10/1000*$C$33)+(D10/1000*$C$35)+(E10/1000*$C$34)) -> 0.30901727
B13: municipal waste incineration, at incineration plant, with wet air pollution control, without flue gas condensation, with electricity and heat recovery, energy allocation | C13: 1000 | D13: 628 | E13: 6170 | F13: 0 | G13: =(D13*3.6)/((D13*3.6)+E13) -> 0.26815961 | H13: =(E13)/((D13*3.6)+E13) -> 0.73184039
B14: municipal waste incineration, at incineration plant, with wet air pollution control, without flue gas condensation, with electricity and heat recovery, exergy allocation | I14: 0 | J14: =1-K14 -> 0.74318404 | K14: =(G42*F42)/((G42*F42)+(1*H42)) -> 0.25681596
B15: municipal waste incineration, at incineration plant, with wet air pollution control, without flue gas condensation, with electricity and heat recovery, economic allocation | L15: =(C13/1000*$C$33)/((C13/1000*$C$33)+(D13/1000*$C$35)+(E13/1000*$C$34)) -> 0.49166938 | M15: =(D13/1000*$C$35)/((C13/1000*$C$33)+(D13/1000*$C$35)+(E13/1000*$C$34)) -> 0.24900675 | N15: =(E13/1000*$C$34)/((C13/1000*$C$33)+(D13/1000*$C$35)+(E13/1000*$C$34)) -> 0.25932388
B16: municipal waste incineration, at incineration plant, with wet air pollution control, with flue gas condensation, with electricity and heat recovery, energy allocation | C16: 1000 | D16: 618 | E16: 7860 | F16: 0 | G16: =(D16*3.6)/((D16*3.6)+E16) -> 0.22060923 | H16: =(E16)/((D16*3.6)+E16) -> 0.77939077
B17: municipal waste incineration, at incineration plant, with wet air pollution control, with flue gas condensation, with electricity and heat recovery, exergy allocation | I17: 0 | J17: =1-K17 -> 0.6909244 | K17: =(G43*F43)/((G43*F43)+(1*H43)) -> 0.3090756
B18: municipal waste incineration, at incineration plant, with wet air pollution control, with flue gas condensation, with electricity and heat recovery, economic allocation | L18: =(C16/1000*$C$33)/((C16/1000*$C$33)+(D16/1000*$C$35)+(E16/1000*$C$34)) -> 0.46076785 | M18: =(D16/1000*$C$35)/((C16/1000*$C$33)+(D16/1000*$C$35)+(E16/1000*$C$34)) -> 0.22964075 | N18: =(E16/1000*$C$34)/((C16/1000*$C$33)+(D16/1000*$C$35)+(E16/1000*$C$34)) -> 0.3095914
B19: municipal waste incineration, at incineration plant, with semi-dry air pollution control, with flue gas condensation, with electricity recovery only, with carbon capture and storage, energy allocation | C19: 1000 | D19: 478 | F19: 0 | G19: =(D19*3.6)/((D19*3.6)+E19) -> 1 | H19: =(E19)/((D19*3.6)+E19) -> 0
B20: municipal waste incineration, at incineration plant, with semi-dry air pollution control, with flue gas condensation, with electricity recovery only, with carbon capture and storage, exergy allocation | I20: 0 | J20: =1-K20 -> 1 | K20: =(G44*F44)/((G44*F44)+(1*H44)) -> 0
B21: municipal waste incineration, at incineration plant, with semi-dry air pollution control, with flue gas condensation, with electricity recovery only, with carbon capture and storage, economic allocation | L21: =(C19/1000*$C$33)/((C19/1000*$C$33)+(D19/1000*$C$35)+(E19/1000*$C$34)) -> 0.7217695 | M21: =(D19/1000*$C$35)/((C19/1000*$C$33)+(D19/1000*$C$35)+(E19/1000*$C$34)) -> 0.2782305 | N21: =(E19/1000*$C$34)/((C19/1000*$C$33)+(D19/1000*$C$35)+(E19/1000*$C$34)) -> 0
B22: municipal waste incineration, at incineration plant, with semi-dry air pollution control, with flue gas condensation, with electricity and heat recovery, with carbon capture and storage, energy allocation | C22: 1000 | D22: 312 | E22: 7400 | F22: 0 | G22: =(D22*3.6)/((D22*3.6)+E22) -> 0.13178149 | H22: =(E22)/((D22*3.6)+E22) -> 0.86821851
B23: municipal waste incineration, at incineration plant, with semi-dry air pollution control, with flue gas condensation, with electricity and heat recovery, with carbon capture and storage, exergy allocation | I23: 0 | J23: =1-K23 -> 0.54519278 | K23: =(G45*F45)/((G45*F45)+(1*H45)) -> 0.45480722
B24: municipal waste incineration, at incineration plant, with semi-dry air pollution control, with flue gas condensation, with electricity and heat recovery, with carbon capture and storage, economic allocation | L24: =(C22/1000*$C$33)/((C22/1000*$C$33)+(D22/1000*$C$35)+(E22/1000*$C$34)) -> 0.53073104 | M24: =(D22/1000*$C$35)/((C22/1000*$C$33)+(D22/1000*$C$35)+(E22/1000*$C$34)) -> 0.13353878 | N24: =(E22/1000*$C$34)/((C22/1000*$C$33)+(D22/1000*$C$35)+(E22/1000*$C$34)) -> 0.33573018
B25: municipal waste incineration, at incineration plant, with wet air pollution control, with flue gas condensation, with electricity and heat recovery, with carbon capture and storage, energy allocation | C25: 1000 | D25: 317 | E25: 7400 | F25: 0 | G25: =(D25*3.6)/((D25*3.6)+E25) -> 0.1336112 | H25: =(E25)/((D25*3.6)+E25) -> 0.8663888
B26: municipal waste incineration, at incineration plant, with wet air pollution control, with flue gas condensation, with electricity and heat recovery, with carbon capture and storage, exergy allocation | I26: 0 | J26: =1-K26 -> 0.54913204 | K26: =(G46*F46)/((G46*F46)+(1*H46)) -> 0.45086796
B27: municipal waste incineration, at incineration plant, with wet air pollution control, with flue gas condensation, with electricity and heat recovery, with carbon capture and storage, economic allocation | L27: =(C25/1000*$C$33)/((C25/1000*$C$33)+(D25/1000*$C$35)+(E25/1000*$C$34)) -> 0.52959768 | M27: =(D25/1000*$C$35)/((C25/1000*$C$33)+(D25/1000*$C$35)+(E25/1000*$C$34)) -> 0.13538908 | N27: =(E25/1000*$C$34)/((C25/1000*$C$33)+(D25/1000*$C$35)+(E25/1000*$C$34)) -> 0.33501324
B28: municipal waste incineration, at incineration plant, with wet air pollution control, with flue gas condensation, with electricity and optimized heat recovery, with carbon capture and storage, energy allocation | C28: 1000 | D28: 473 | E28: 8510 | F28: 0 | G28: =(D28*3.6)/((D28*3.6)+E28) -> 0.16673194 | H28: =(E28)/((D28*3.6)+E28) -> 0.83326806
